Watching for file changes with StatReloader
Watching for file changes with StatReloader
Watching for file changes with StatReloader
Invalid HTTP_HOST header: '127.0.0.1:8000'. You may need to add '127.0.0.1' to ALLOWED_HOSTS.
Bad Request: /
"GET / HTTP/1.1" 400 66448
Invalid HTTP_HOST header: '127.0.0.1:8000'. You may need to add '127.0.0.1' to ALLOWED_HOSTS.
Bad Request: /favicon.ico
"GET /favicon.ico HTTP/1.1" 400 66515
Not Found: /
"GET / HTTP/1.1" 404 2155
Not Found: /apple-touch-icon-precomposed.png
"GET /apple-touch-icon-precomposed.png HTTP/1.1" 404 2269
Not Found: /apple-touch-icon.png
"GET /apple-touch-icon.png HTTP/1.1" 404 2233
Not Found: /
"GET / HTTP/1.1" 404 2155
Not Found: /
"GET / HTTP/1.1" 404 2155
Not Found: /
"GET / HTTP/1.1" 404 2155
Not Found: /core
"GET /core HTTP/1.1" 404 2185
Not Found: /core/
"GET /core/ HTTP/1.1" 404 7206
"GET /core/api HTTP/1.1" 301 0
"GET /core/api/ HTTP/1.1" 200 8233
"GET /static/rest_framework/css/bootstrap.min.css HTTP/1.1" 200 121457
"GET /static/rest_framework/css/bootstrap-tweaks.css HTTP/1.1" 200 3385
"GET /static/rest_framework/js/ajax-form.js HTTP/1.1" 200 3597
"GET /static/rest_framework/css/default.css HTTP/1.1" 200 1131
"GET /static/rest_framework/css/prettify.css HTTP/1.1" 200 817
"GET /static/rest_framework/js/csrf.js HTTP/1.1" 200 1719
"GET /static/rest_framework/js/bootstrap.min.js HTTP/1.1" 200 39680
"GET /static/rest_framework/js/default.js HTTP/1.1" 200 1268
"GET /static/rest_framework/js/prettify-min.js HTTP/1.1" 200 13632
"GET /static/rest_framework/js/jquery-3.5.1.min.js HTTP/1.1" 200 89476
"GET /static/rest_framework/img/grid.png HTTP/1.1" 200 1458
Method Not Allowed: /core/api/register-customer/
"GET /core/api/register-customer/ HTTP/1.1" 405 5821
/Users/bedeabbe/Desktop/projects/python/project_h_backend/project_h_core/serializers.py changed, reloading.
Watching for file changes with StatReloader
Bad Request: /core/api/register-customer/
"POST /core/api/register-customer/ HTTP/1.1" 400 5819
Internal Server Error: /core/api/register-customer
Traceback (most recent call last):
  File "/Users/bedeabbe/Desktop/projects/python/venv/lib/python3.9/site-packages/django/core/handlers/exception.py", line 47, in inner
    response = get_response(request)
  File "/Users/bedeabbe/Desktop/projects/python/venv/lib/python3.9/site-packages/django/utils/deprecation.py", line 113, in __call__
    response = self.process_request(request)
  File "/Users/bedeabbe/Desktop/projects/python/venv/lib/python3.9/site-packages/django/middleware/common.py", line 54, in process_request
    path = self.get_full_path_with_slash(request)
  File "/Users/bedeabbe/Desktop/projects/python/venv/lib/python3.9/site-packages/django/middleware/common.py", line 87, in get_full_path_with_slash
    raise RuntimeError(
RuntimeError: You called this URL via POST, but the URL doesn't end in a slash and you have APPEND_SLASH set. Django can't redirect to the slash URL while maintaining POST data. Change your form to point to localhost:8000/core/api/register-customer/ (note the trailing slash), or set APPEND_SLASH=False in your Django settings.
"POST /core/api/register-customer HTTP/1.1" 500 66885
About to save user 
{'mobile_number': '0557881327', 'first_name': 'Jake', 'last_name': 'Banky', 'email': 'jake.banky@gmail.com', 'gender': 'm', 'address': 'Fillin Street 229', 'password': 'jake1234'}
Internal Server Error: /core/api/register-customer/
Traceback (most recent call last):
  File "/Users/bedeabbe/Desktop/projects/python/venv/lib/python3.9/site-packages/django/core/handlers/exception.py", line 47, in inner
    response = get_response(request)
  File "/Users/bedeabbe/Desktop/projects/python/venv/lib/python3.9/site-packages/django/core/handlers/base.py", line 181, in _get_response
    response = wrapped_callback(request, *callback_args, **callback_kwargs)
  File "/Users/bedeabbe/Desktop/projects/python/venv/lib/python3.9/site-packages/django/views/decorators/csrf.py", line 54, in wrapped_view
    return view_func(*args, **kwargs)
  File "/Users/bedeabbe/Desktop/projects/python/venv/lib/python3.9/site-packages/rest_framework/viewsets.py", line 125, in view
    return self.dispatch(request, *args, **kwargs)
  File "/Users/bedeabbe/Desktop/projects/python/venv/lib/python3.9/site-packages/rest_framework/views.py", line 509, in dispatch
    response = self.handle_exception(exc)
  File "/Users/bedeabbe/Desktop/projects/python/venv/lib/python3.9/site-packages/rest_framework/views.py", line 469, in handle_exception
    self.raise_uncaught_exception(exc)
  File "/Users/bedeabbe/Desktop/projects/python/venv/lib/python3.9/site-packages/rest_framework/views.py", line 480, in raise_uncaught_exception
    raise exc
  File "/Users/bedeabbe/Desktop/projects/python/venv/lib/python3.9/site-packages/rest_framework/views.py", line 506, in dispatch
    response = handler(request, *args, **kwargs)
  File "/Users/bedeabbe/Desktop/projects/python/project_h_backend/project_h_core/auth_and_registration_views/register_views.py", line 33, in create
    logger.info(serializer.data['dob'])
KeyError: 'dob'
"POST /core/api/register-customer/ HTTP/1.1" 500 90610
/Users/bedeabbe/Desktop/projects/python/project_h_backend/project_h_core/auth_and_registration_views/register_views.py changed, reloading.
Watching for file changes with StatReloader
About to save user 
{'mobile_number': '0557881327', 'first_name': 'Jake', 'last_name': 'Banky', 'email': 'jake.banky@gmail.com', 'gender': 'm', 'address': 'Fillin Street 229', 'password': 'jake1234'}
<built-in method today of type object at 0x104df9d38>
image is 
About to save customer details 
2024040414
Picture not there 
Internal Server Error: /core/api/register-customer/
Traceback (most recent call last):
  File "/Users/bedeabbe/Desktop/projects/python/venv/lib/python3.9/site-packages/django/core/handlers/exception.py", line 47, in inner
    response = get_response(request)
  File "/Users/bedeabbe/Desktop/projects/python/venv/lib/python3.9/site-packages/django/core/handlers/base.py", line 181, in _get_response
    response = wrapped_callback(request, *callback_args, **callback_kwargs)
  File "/Users/bedeabbe/Desktop/projects/python/venv/lib/python3.9/site-packages/django/views/decorators/csrf.py", line 54, in wrapped_view
    return view_func(*args, **kwargs)
  File "/Users/bedeabbe/Desktop/projects/python/venv/lib/python3.9/site-packages/rest_framework/viewsets.py", line 125, in view
    return self.dispatch(request, *args, **kwargs)
  File "/Users/bedeabbe/Desktop/projects/python/venv/lib/python3.9/site-packages/rest_framework/views.py", line 509, in dispatch
    response = self.handle_exception(exc)
  File "/Users/bedeabbe/Desktop/projects/python/venv/lib/python3.9/site-packages/rest_framework/views.py", line 469, in handle_exception
    self.raise_uncaught_exception(exc)
  File "/Users/bedeabbe/Desktop/projects/python/venv/lib/python3.9/site-packages/rest_framework/views.py", line 480, in raise_uncaught_exception
    raise exc
  File "/Users/bedeabbe/Desktop/projects/python/venv/lib/python3.9/site-packages/rest_framework/views.py", line 506, in dispatch
    response = handler(request, *args, **kwargs)
  File "/Users/bedeabbe/Desktop/projects/python/project_h_backend/project_h_core/auth_and_registration_views/register_views.py", line 76, in create
    dob=serializer.data['dob'],
KeyError: 'dob'
"POST /core/api/register-customer/ HTTP/1.1" 500 91325
About to save user 
{'mobile_number': '0557881327', 'first_name': 'Jake', 'last_name': 'Banky', 'email': 'jake.banky@gmail.com', 'gender': 'm', 'address': 'Fillin Street 229', 'password': 'jake1234', 'dob': '2001-04-29'}
<built-in method today of type object at 0x104df9d38>
image is 
About to save customer details 
2024040415
Picture not there 
Customer saved 
"POST /core/api/register-customer/ HTTP/1.1" 202 857
/Users/bedeabbe/Desktop/projects/python/project_h_backend/project_h_core/auth_and_registration_views/register_views.py changed, reloading.
Watching for file changes with StatReloader
About to save user 
{'mobile_number': '0557881327', 'first_name': 'Jake', 'last_name': 'Banky', 'email': 'jake.banky@gmail.com', 'gender': 'm', 'address': 'Fillin Street 229', 'password': 'jake1234', 'dob': '2001-04-29'}
<built-in method today of type object at 0x1025a5d38>
image is 
Internal Server Error: /core/api/register-customer/
Traceback (most recent call last):
  File "/Users/bedeabbe/Desktop/projects/python/venv/lib/python3.9/site-packages/django/utils/module_loading.py", line 20, in import_string
    return getattr(module, class_name)
AttributeError: module 'django.contrib.auth.hashers' has no attribute 'ScryptPasswordHasher'

The above exception was the direct cause of the following exception:

Traceback (most recent call last):
  File "/Users/bedeabbe/Desktop/projects/python/venv/lib/python3.9/site-packages/django/core/handlers/exception.py", line 47, in inner
    response = get_response(request)
  File "/Users/bedeabbe/Desktop/projects/python/venv/lib/python3.9/site-packages/django/core/handlers/base.py", line 181, in _get_response
    response = wrapped_callback(request, *callback_args, **callback_kwargs)
  File "/Users/bedeabbe/Desktop/projects/python/venv/lib/python3.9/site-packages/django/views/decorators/csrf.py", line 54, in wrapped_view
    return view_func(*args, **kwargs)
  File "/Users/bedeabbe/Desktop/projects/python/venv/lib/python3.9/site-packages/rest_framework/viewsets.py", line 125, in view
    return self.dispatch(request, *args, **kwargs)
  File "/Users/bedeabbe/Desktop/projects/python/venv/lib/python3.9/site-packages/rest_framework/views.py", line 509, in dispatch
    response = self.handle_exception(exc)
  File "/Users/bedeabbe/Desktop/projects/python/venv/lib/python3.9/site-packages/rest_framework/views.py", line 469, in handle_exception
    self.raise_uncaught_exception(exc)
  File "/Users/bedeabbe/Desktop/projects/python/venv/lib/python3.9/site-packages/rest_framework/views.py", line 480, in raise_uncaught_exception
    raise exc
  File "/Users/bedeabbe/Desktop/projects/python/venv/lib/python3.9/site-packages/rest_framework/views.py", line 506, in dispatch
    response = handler(request, *args, **kwargs)
  File "/Users/bedeabbe/Desktop/projects/python/project_h_backend/project_h_core/auth_and_registration_views/register_views.py", line 39, in create
    save_user = User.objects.create_user(
  File "/Users/bedeabbe/Desktop/projects/python/venv/lib/python3.9/site-packages/django/contrib/auth/models.py", line 146, in create_user
    return self._create_user(username, email, password, **extra_fields)
  File "/Users/bedeabbe/Desktop/projects/python/venv/lib/python3.9/site-packages/django/contrib/auth/models.py", line 139, in _create_user
    user.set_password(password)
  File "/Users/bedeabbe/Desktop/projects/python/venv/lib/python3.9/site-packages/django/contrib/auth/base_user.py", line 99, in set_password
    self.password = make_password(raw_password)
  File "/Users/bedeabbe/Desktop/projects/python/venv/lib/python3.9/site-packages/django/contrib/auth/hashers.py", line 80, in make_password
    hasher = get_hasher(hasher)
  File "/Users/bedeabbe/Desktop/projects/python/venv/lib/python3.9/site-packages/django/contrib/auth/hashers.py", line 121, in get_hasher
    return get_hashers()[0]
  File "/Users/bedeabbe/Desktop/projects/python/venv/lib/python3.9/site-packages/django/contrib/auth/hashers.py", line 89, in get_hashers
    hasher_cls = import_string(hasher_path)
  File "/Users/bedeabbe/Desktop/projects/python/venv/lib/python3.9/site-packages/django/utils/module_loading.py", line 22, in import_string
    raise ImportError('Module "%s" does not define a "%s" attribute/class' % (
ImportError: Module "django.contrib.auth.hashers" does not define a "ScryptPasswordHasher" attribute/class
"POST /core/api/register-customer/ HTTP/1.1" 500 126016
/Users/bedeabbe/Desktop/projects/python/project_h_backend/project_h/settings.py changed, reloading.
Watching for file changes with StatReloader
About to save user 
{'mobile_number': '0557881327', 'first_name': 'Jake', 'last_name': 'Banky', 'email': 'jake.banky@gmail.com', 'gender': 'm', 'address': 'Fillin Street 229', 'password': 'jake1234', 'dob': '2001-04-29'}
<built-in method today of type object at 0x1027b1d38>
image is 
Internal Server Error: /core/api/register-customer/
Traceback (most recent call last):
  File "/Users/bedeabbe/Desktop/projects/python/venv/lib/python3.9/site-packages/django/utils/module_loading.py", line 20, in import_string
    return getattr(module, class_name)
AttributeError: module 'django.contrib.auth.hashers' has no attribute 'ScryptPasswordHasher'

The above exception was the direct cause of the following exception:

Traceback (most recent call last):
  File "/Users/bedeabbe/Desktop/projects/python/venv/lib/python3.9/site-packages/django/core/handlers/exception.py", line 47, in inner
    response = get_response(request)
  File "/Users/bedeabbe/Desktop/projects/python/venv/lib/python3.9/site-packages/django/core/handlers/base.py", line 181, in _get_response
    response = wrapped_callback(request, *callback_args, **callback_kwargs)
  File "/Users/bedeabbe/Desktop/projects/python/venv/lib/python3.9/site-packages/django/views/decorators/csrf.py", line 54, in wrapped_view
    return view_func(*args, **kwargs)
  File "/Users/bedeabbe/Desktop/projects/python/venv/lib/python3.9/site-packages/rest_framework/viewsets.py", line 125, in view
    return self.dispatch(request, *args, **kwargs)
  File "/Users/bedeabbe/Desktop/projects/python/venv/lib/python3.9/site-packages/rest_framework/views.py", line 509, in dispatch
    response = self.handle_exception(exc)
  File "/Users/bedeabbe/Desktop/projects/python/venv/lib/python3.9/site-packages/rest_framework/views.py", line 469, in handle_exception
    self.raise_uncaught_exception(exc)
  File "/Users/bedeabbe/Desktop/projects/python/venv/lib/python3.9/site-packages/rest_framework/views.py", line 480, in raise_uncaught_exception
    raise exc
  File "/Users/bedeabbe/Desktop/projects/python/venv/lib/python3.9/site-packages/rest_framework/views.py", line 506, in dispatch
    response = handler(request, *args, **kwargs)
  File "/Users/bedeabbe/Desktop/projects/python/project_h_backend/project_h_core/auth_and_registration_views/register_views.py", line 39, in create
    save_user = User.objects.create_user(
  File "/Users/bedeabbe/Desktop/projects/python/venv/lib/python3.9/site-packages/django/contrib/auth/models.py", line 146, in create_user
    return self._create_user(username, email, password, **extra_fields)
  File "/Users/bedeabbe/Desktop/projects/python/venv/lib/python3.9/site-packages/django/contrib/auth/models.py", line 139, in _create_user
    user.set_password(password)
  File "/Users/bedeabbe/Desktop/projects/python/venv/lib/python3.9/site-packages/django/contrib/auth/base_user.py", line 99, in set_password
    self.password = make_password(raw_password)
  File "/Users/bedeabbe/Desktop/projects/python/venv/lib/python3.9/site-packages/django/contrib/auth/hashers.py", line 80, in make_password
    hasher = get_hasher(hasher)
  File "/Users/bedeabbe/Desktop/projects/python/venv/lib/python3.9/site-packages/django/contrib/auth/hashers.py", line 121, in get_hasher
    return get_hashers()[0]
  File "/Users/bedeabbe/Desktop/projects/python/venv/lib/python3.9/site-packages/django/contrib/auth/hashers.py", line 89, in get_hashers
    hasher_cls = import_string(hasher_path)
  File "/Users/bedeabbe/Desktop/projects/python/venv/lib/python3.9/site-packages/django/utils/module_loading.py", line 22, in import_string
    raise ImportError('Module "%s" does not define a "%s" attribute/class' % (
ImportError: Module "django.contrib.auth.hashers" does not define a "ScryptPasswordHasher" attribute/class
"POST /core/api/register-customer/ HTTP/1.1" 500 125221
/Users/bedeabbe/Desktop/projects/python/project_h_backend/project_h_core/auth_and_registration_views/register_views.py changed, reloading.
Watching for file changes with StatReloader
About to save user 
{'mobile_number': '0557881327', 'first_name': 'Jake', 'last_name': 'Banky', 'email': 'jake.banky@gmail.com', 'gender': 'm', 'address': 'Fillin Street 229', 'password': 'jake1234', 'dob': '2001-04-29'}
<built-in method today of type object at 0x1049fdd38>
image is 
Internal Server Error: /core/api/register-customer/
Traceback (most recent call last):
  File "/Users/bedeabbe/Desktop/projects/python/venv/lib/python3.9/site-packages/django/utils/module_loading.py", line 20, in import_string
    return getattr(module, class_name)
AttributeError: module 'django.contrib.auth.hashers' has no attribute 'ScryptPasswordHasher'

The above exception was the direct cause of the following exception:

Traceback (most recent call last):
  File "/Users/bedeabbe/Desktop/projects/python/venv/lib/python3.9/site-packages/django/core/handlers/exception.py", line 47, in inner
    response = get_response(request)
  File "/Users/bedeabbe/Desktop/projects/python/venv/lib/python3.9/site-packages/django/core/handlers/base.py", line 181, in _get_response
    response = wrapped_callback(request, *callback_args, **callback_kwargs)
  File "/Users/bedeabbe/Desktop/projects/python/venv/lib/python3.9/site-packages/django/views/decorators/csrf.py", line 54, in wrapped_view
    return view_func(*args, **kwargs)
  File "/Users/bedeabbe/Desktop/projects/python/venv/lib/python3.9/site-packages/rest_framework/viewsets.py", line 125, in view
    return self.dispatch(request, *args, **kwargs)
  File "/Users/bedeabbe/Desktop/projects/python/venv/lib/python3.9/site-packages/rest_framework/views.py", line 509, in dispatch
    response = self.handle_exception(exc)
  File "/Users/bedeabbe/Desktop/projects/python/venv/lib/python3.9/site-packages/rest_framework/views.py", line 469, in handle_exception
    self.raise_uncaught_exception(exc)
  File "/Users/bedeabbe/Desktop/projects/python/venv/lib/python3.9/site-packages/rest_framework/views.py", line 480, in raise_uncaught_exception
    raise exc
  File "/Users/bedeabbe/Desktop/projects/python/venv/lib/python3.9/site-packages/rest_framework/views.py", line 506, in dispatch
    response = handler(request, *args, **kwargs)
  File "/Users/bedeabbe/Desktop/projects/python/project_h_backend/project_h_core/auth_and_registration_views/register_views.py", line 38, in create
    save_user = User.objects.create_user(
  File "/Users/bedeabbe/Desktop/projects/python/venv/lib/python3.9/site-packages/django/contrib/auth/models.py", line 146, in create_user
    return self._create_user(username, email, password, **extra_fields)
  File "/Users/bedeabbe/Desktop/projects/python/venv/lib/python3.9/site-packages/django/contrib/auth/models.py", line 139, in _create_user
    user.set_password(password)
  File "/Users/bedeabbe/Desktop/projects/python/venv/lib/python3.9/site-packages/django/contrib/auth/base_user.py", line 99, in set_password
    self.password = make_password(raw_password)
  File "/Users/bedeabbe/Desktop/projects/python/venv/lib/python3.9/site-packages/django/contrib/auth/hashers.py", line 80, in make_password
    hasher = get_hasher(hasher)
  File "/Users/bedeabbe/Desktop/projects/python/venv/lib/python3.9/site-packages/django/contrib/auth/hashers.py", line 121, in get_hasher
    return get_hashers()[0]
  File "/Users/bedeabbe/Desktop/projects/python/venv/lib/python3.9/site-packages/django/contrib/auth/hashers.py", line 89, in get_hashers
    hasher_cls = import_string(hasher_path)
  File "/Users/bedeabbe/Desktop/projects/python/venv/lib/python3.9/site-packages/django/utils/module_loading.py", line 22, in import_string
    raise ImportError('Module "%s" does not define a "%s" attribute/class' % (
ImportError: Module "django.contrib.auth.hashers" does not define a "ScryptPasswordHasher" attribute/class
"POST /core/api/register-customer/ HTTP/1.1" 500 125221
About to save user 
{'mobile_number': '0557881327', 'first_name': 'Jake', 'last_name': 'Banky', 'email': 'jake.banky@gmail.com', 'gender': 'm', 'address': 'Fillin Street 229', 'password': 'jake1234', 'dob': '2001-04-29'}
<built-in method today of type object at 0x1049fdd38>
image is 
Internal Server Error: /core/api/register-customer/
Traceback (most recent call last):
  File "/Users/bedeabbe/Desktop/projects/python/venv/lib/python3.9/site-packages/django/utils/module_loading.py", line 20, in import_string
    return getattr(module, class_name)
AttributeError: module 'django.contrib.auth.hashers' has no attribute 'ScryptPasswordHasher'

The above exception was the direct cause of the following exception:

Traceback (most recent call last):
  File "/Users/bedeabbe/Desktop/projects/python/venv/lib/python3.9/site-packages/django/core/handlers/exception.py", line 47, in inner
    response = get_response(request)
  File "/Users/bedeabbe/Desktop/projects/python/venv/lib/python3.9/site-packages/django/core/handlers/base.py", line 181, in _get_response
    response = wrapped_callback(request, *callback_args, **callback_kwargs)
  File "/Users/bedeabbe/Desktop/projects/python/venv/lib/python3.9/site-packages/django/views/decorators/csrf.py", line 54, in wrapped_view
    return view_func(*args, **kwargs)
  File "/Users/bedeabbe/Desktop/projects/python/venv/lib/python3.9/site-packages/rest_framework/viewsets.py", line 125, in view
    return self.dispatch(request, *args, **kwargs)
  File "/Users/bedeabbe/Desktop/projects/python/venv/lib/python3.9/site-packages/rest_framework/views.py", line 509, in dispatch
    response = self.handle_exception(exc)
  File "/Users/bedeabbe/Desktop/projects/python/venv/lib/python3.9/site-packages/rest_framework/views.py", line 469, in handle_exception
    self.raise_uncaught_exception(exc)
  File "/Users/bedeabbe/Desktop/projects/python/venv/lib/python3.9/site-packages/rest_framework/views.py", line 480, in raise_uncaught_exception
    raise exc
  File "/Users/bedeabbe/Desktop/projects/python/venv/lib/python3.9/site-packages/rest_framework/views.py", line 506, in dispatch
    response = handler(request, *args, **kwargs)
  File "/Users/bedeabbe/Desktop/projects/python/project_h_backend/project_h_core/auth_and_registration_views/register_views.py", line 38, in create
    save_user = User.objects.create_user(
  File "/Users/bedeabbe/Desktop/projects/python/venv/lib/python3.9/site-packages/django/contrib/auth/models.py", line 146, in create_user
    return self._create_user(username, email, password, **extra_fields)
  File "/Users/bedeabbe/Desktop/projects/python/venv/lib/python3.9/site-packages/django/contrib/auth/models.py", line 139, in _create_user
    user.set_password(password)
  File "/Users/bedeabbe/Desktop/projects/python/venv/lib/python3.9/site-packages/django/contrib/auth/base_user.py", line 99, in set_password
    self.password = make_password(raw_password)
  File "/Users/bedeabbe/Desktop/projects/python/venv/lib/python3.9/site-packages/django/contrib/auth/hashers.py", line 80, in make_password
    hasher = get_hasher(hasher)
  File "/Users/bedeabbe/Desktop/projects/python/venv/lib/python3.9/site-packages/django/contrib/auth/hashers.py", line 121, in get_hasher
    return get_hashers()[0]
  File "/Users/bedeabbe/Desktop/projects/python/venv/lib/python3.9/site-packages/django/contrib/auth/hashers.py", line 89, in get_hashers
    hasher_cls = import_string(hasher_path)
  File "/Users/bedeabbe/Desktop/projects/python/venv/lib/python3.9/site-packages/django/utils/module_loading.py", line 22, in import_string
    raise ImportError('Module "%s" does not define a "%s" attribute/class' % (
ImportError: Module "django.contrib.auth.hashers" does not define a "ScryptPasswordHasher" attribute/class
"POST /core/api/register-customer/ HTTP/1.1" 500 125221
/Users/bedeabbe/Desktop/projects/python/project_h_backend/project_h/settings.py changed, reloading.
Watching for file changes with StatReloader
About to save user 
{'mobile_number': '0557881327', 'first_name': 'Jake', 'last_name': 'Banky', 'email': 'jake.banky@gmail.com', 'gender': 'm', 'address': 'Fillin Street 229', 'password': 'jake1234', 'dob': '2001-04-29'}
<built-in method today of type object at 0x10318dd38>
image is 
Internal Server Error: /core/api/register-customer/
Traceback (most recent call last):
  File "/Users/bedeabbe/Desktop/projects/python/venv/lib/python3.9/site-packages/django/core/handlers/exception.py", line 47, in inner
    response = get_response(request)
  File "/Users/bedeabbe/Desktop/projects/python/venv/lib/python3.9/site-packages/django/core/handlers/base.py", line 181, in _get_response
    response = wrapped_callback(request, *callback_args, **callback_kwargs)
  File "/Users/bedeabbe/Desktop/projects/python/venv/lib/python3.9/site-packages/django/views/decorators/csrf.py", line 54, in wrapped_view
    return view_func(*args, **kwargs)
  File "/Users/bedeabbe/Desktop/projects/python/venv/lib/python3.9/site-packages/rest_framework/viewsets.py", line 125, in view
    return self.dispatch(request, *args, **kwargs)
  File "/Users/bedeabbe/Desktop/projects/python/venv/lib/python3.9/site-packages/rest_framework/views.py", line 509, in dispatch
    response = self.handle_exception(exc)
  File "/Users/bedeabbe/Desktop/projects/python/venv/lib/python3.9/site-packages/rest_framework/views.py", line 469, in handle_exception
    self.raise_uncaught_exception(exc)
  File "/Users/bedeabbe/Desktop/projects/python/venv/lib/python3.9/site-packages/rest_framework/views.py", line 480, in raise_uncaught_exception
    raise exc
  File "/Users/bedeabbe/Desktop/projects/python/venv/lib/python3.9/site-packages/rest_framework/views.py", line 506, in dispatch
    response = handler(request, *args, **kwargs)
  File "/Users/bedeabbe/Desktop/projects/python/project_h_backend/project_h_core/auth_and_registration_views/register_views.py", line 38, in create
    save_user = User.objects.create_user(
  File "/Users/bedeabbe/Desktop/projects/python/venv/lib/python3.9/site-packages/django/contrib/auth/models.py", line 146, in create_user
    return self._create_user(username, email, password, **extra_fields)
  File "/Users/bedeabbe/Desktop/projects/python/venv/lib/python3.9/site-packages/django/contrib/auth/models.py", line 139, in _create_user
    user.set_password(password)
  File "/Users/bedeabbe/Desktop/projects/python/venv/lib/python3.9/site-packages/django/contrib/auth/base_user.py", line 99, in set_password
    self.password = make_password(raw_password)
  File "/Users/bedeabbe/Desktop/projects/python/venv/lib/python3.9/site-packages/django/contrib/auth/hashers.py", line 80, in make_password
    hasher = get_hasher(hasher)
  File "/Users/bedeabbe/Desktop/projects/python/venv/lib/python3.9/site-packages/django/contrib/auth/hashers.py", line 121, in get_hasher
    return get_hashers()[0]
  File "/Users/bedeabbe/Desktop/projects/python/venv/lib/python3.9/site-packages/django/contrib/auth/hashers.py", line 89, in get_hashers
    hasher_cls = import_string(hasher_path)
  File "/Users/bedeabbe/Desktop/projects/python/venv/lib/python3.9/site-packages/django/utils/module_loading.py", line 17, in import_string
    module = import_module(module_path)
  File "/Applications/Xcode.app/Contents/Developer/Library/Frameworks/Python3.framework/Versions/3.9/lib/python3.9/importlib/__init__.py", line 127, in import_module
    return _bootstrap._gcd_import(name[level:], package, level)
  File "<frozen importlib._bootstrap>", line 1030, in _gcd_import
  File "<frozen importlib._bootstrap>", line 1007, in _find_and_load
  File "<frozen importlib._bootstrap>", line 972, in _find_and_load_unlocked
  File "<frozen importlib._bootstrap>", line 228, in _call_with_frames_removed
  File "<frozen importlib._bootstrap>", line 1030, in _gcd_import
  File "<frozen importlib._bootstrap>", line 1007, in _find_and_load
  File "<frozen importlib._bootstrap>", line 984, in _find_and_load_unlocked
ModuleNotFoundError: No module named 'django_scrypt'
"POST /core/api/register-customer/ HTTP/1.1" 500 135799
Watching for file changes with StatReloader
About to save user 
{'mobile_number': '0557881327', 'first_name': 'Jake', 'last_name': 'Banky', 'email': 'jake.banky@gmail.com', 'gender': 'm', 'address': 'Fillin Street 229', 'password': 'jake1234', 'dob': '2001-04-29'}
<built-in method today of type object at 0x1011edd38>
image is 
Internal Server Error: /core/api/register-customer/
Traceback (most recent call last):
  File "/Users/bedeabbe/Desktop/projects/python/venv/lib/python3.9/site-packages/django/core/handlers/exception.py", line 47, in inner
    response = get_response(request)
  File "/Users/bedeabbe/Desktop/projects/python/venv/lib/python3.9/site-packages/django/core/handlers/base.py", line 181, in _get_response
    response = wrapped_callback(request, *callback_args, **callback_kwargs)
  File "/Users/bedeabbe/Desktop/projects/python/venv/lib/python3.9/site-packages/django/views/decorators/csrf.py", line 54, in wrapped_view
    return view_func(*args, **kwargs)
  File "/Users/bedeabbe/Desktop/projects/python/venv/lib/python3.9/site-packages/rest_framework/viewsets.py", line 125, in view
    return self.dispatch(request, *args, **kwargs)
  File "/Users/bedeabbe/Desktop/projects/python/venv/lib/python3.9/site-packages/rest_framework/views.py", line 509, in dispatch
    response = self.handle_exception(exc)
  File "/Users/bedeabbe/Desktop/projects/python/venv/lib/python3.9/site-packages/rest_framework/views.py", line 469, in handle_exception
    self.raise_uncaught_exception(exc)
  File "/Users/bedeabbe/Desktop/projects/python/venv/lib/python3.9/site-packages/rest_framework/views.py", line 480, in raise_uncaught_exception
    raise exc
  File "/Users/bedeabbe/Desktop/projects/python/venv/lib/python3.9/site-packages/rest_framework/views.py", line 506, in dispatch
    response = handler(request, *args, **kwargs)
  File "/Users/bedeabbe/Desktop/projects/python/project_h_backend/project_h_core/auth_and_registration_views/register_views.py", line 38, in create
    save_user = User.objects.create_user(
  File "/Users/bedeabbe/Desktop/projects/python/venv/lib/python3.9/site-packages/django/contrib/auth/models.py", line 146, in create_user
    return self._create_user(username, email, password, **extra_fields)
  File "/Users/bedeabbe/Desktop/projects/python/venv/lib/python3.9/site-packages/django/contrib/auth/models.py", line 139, in _create_user
    user.set_password(password)
  File "/Users/bedeabbe/Desktop/projects/python/venv/lib/python3.9/site-packages/django/contrib/auth/base_user.py", line 99, in set_password
    self.password = make_password(raw_password)
  File "/Users/bedeabbe/Desktop/projects/python/venv/lib/python3.9/site-packages/django/contrib/auth/hashers.py", line 80, in make_password
    hasher = get_hasher(hasher)
  File "/Users/bedeabbe/Desktop/projects/python/venv/lib/python3.9/site-packages/django/contrib/auth/hashers.py", line 121, in get_hasher
    return get_hashers()[0]
  File "/Users/bedeabbe/Desktop/projects/python/venv/lib/python3.9/site-packages/django/contrib/auth/hashers.py", line 89, in get_hashers
    hasher_cls = import_string(hasher_path)
  File "/Users/bedeabbe/Desktop/projects/python/venv/lib/python3.9/site-packages/django/utils/module_loading.py", line 17, in import_string
    module = import_module(module_path)
  File "/Applications/Xcode.app/Contents/Developer/Library/Frameworks/Python3.framework/Versions/3.9/lib/python3.9/importlib/__init__.py", line 127, in import_module
    return _bootstrap._gcd_import(name[level:], package, level)
  File "<frozen importlib._bootstrap>", line 1030, in _gcd_import
  File "<frozen importlib._bootstrap>", line 1007, in _find_and_load
  File "<frozen importlib._bootstrap>", line 986, in _find_and_load_unlocked
  File "<frozen importlib._bootstrap>", line 680, in _load_unlocked
  File "<frozen importlib._bootstrap_external>", line 850, in exec_module
  File "<frozen importlib._bootstrap>", line 228, in _call_with_frames_removed
  File "/Users/bedeabbe/Desktop/projects/python/venv/lib/python3.9/site-packages/django_scrypt/hashers.py", line 8, in <module>
    from django.utils.datastructures import SortedDict
ImportError: cannot import name 'SortedDict' from 'django.utils.datastructures' (/Users/bedeabbe/Desktop/projects/python/venv/lib/python3.9/site-packages/django/utils/datastructures.py)
"POST /core/api/register-customer/ HTTP/1.1" 500 154600
/Users/bedeabbe/Desktop/projects/python/project_h_backend/project_h/settings.py changed, reloading.
Watching for file changes with StatReloader
About to save user 
{'mobile_number': '0557881327', 'first_name': 'Jake', 'last_name': 'Banky', 'email': 'jake.banky@gmail.com', 'gender': 'm', 'address': 'Fillin Street 229', 'password': 'jake1234', 'dob': '2001-04-29'}
<built-in method today of type object at 0x1047d1d38>
image is 
Internal Server Error: /core/api/register-customer/
Traceback (most recent call last):
  File "/Users/bedeabbe/Desktop/projects/python/venv/lib/python3.9/site-packages/django/utils/module_loading.py", line 20, in import_string
    return getattr(module, class_name)
AttributeError: module 'django.contrib.auth.hashers' has no attribute 'ScryptPasswordHasher'

The above exception was the direct cause of the following exception:

Traceback (most recent call last):
  File "/Users/bedeabbe/Desktop/projects/python/venv/lib/python3.9/site-packages/django/core/handlers/exception.py", line 47, in inner
    response = get_response(request)
  File "/Users/bedeabbe/Desktop/projects/python/venv/lib/python3.9/site-packages/django/core/handlers/base.py", line 181, in _get_response
    response = wrapped_callback(request, *callback_args, **callback_kwargs)
  File "/Users/bedeabbe/Desktop/projects/python/venv/lib/python3.9/site-packages/django/views/decorators/csrf.py", line 54, in wrapped_view
    return view_func(*args, **kwargs)
  File "/Users/bedeabbe/Desktop/projects/python/venv/lib/python3.9/site-packages/rest_framework/viewsets.py", line 125, in view
    return self.dispatch(request, *args, **kwargs)
  File "/Users/bedeabbe/Desktop/projects/python/venv/lib/python3.9/site-packages/rest_framework/views.py", line 509, in dispatch
    response = self.handle_exception(exc)
  File "/Users/bedeabbe/Desktop/projects/python/venv/lib/python3.9/site-packages/rest_framework/views.py", line 469, in handle_exception
    self.raise_uncaught_exception(exc)
  File "/Users/bedeabbe/Desktop/projects/python/venv/lib/python3.9/site-packages/rest_framework/views.py", line 480, in raise_uncaught_exception
    raise exc
  File "/Users/bedeabbe/Desktop/projects/python/venv/lib/python3.9/site-packages/rest_framework/views.py", line 506, in dispatch
    response = handler(request, *args, **kwargs)
  File "/Users/bedeabbe/Desktop/projects/python/project_h_backend/project_h_core/auth_and_registration_views/register_views.py", line 38, in create
    save_user = User.objects.create_user(
  File "/Users/bedeabbe/Desktop/projects/python/venv/lib/python3.9/site-packages/django/contrib/auth/models.py", line 146, in create_user
    return self._create_user(username, email, password, **extra_fields)
  File "/Users/bedeabbe/Desktop/projects/python/venv/lib/python3.9/site-packages/django/contrib/auth/models.py", line 139, in _create_user
    user.set_password(password)
  File "/Users/bedeabbe/Desktop/projects/python/venv/lib/python3.9/site-packages/django/contrib/auth/base_user.py", line 99, in set_password
    self.password = make_password(raw_password)
  File "/Users/bedeabbe/Desktop/projects/python/venv/lib/python3.9/site-packages/django/contrib/auth/hashers.py", line 80, in make_password
    hasher = get_hasher(hasher)
  File "/Users/bedeabbe/Desktop/projects/python/venv/lib/python3.9/site-packages/django/contrib/auth/hashers.py", line 121, in get_hasher
    return get_hashers()[0]
  File "/Users/bedeabbe/Desktop/projects/python/venv/lib/python3.9/site-packages/django/contrib/auth/hashers.py", line 89, in get_hashers
    hasher_cls = import_string(hasher_path)
  File "/Users/bedeabbe/Desktop/projects/python/venv/lib/python3.9/site-packages/django/utils/module_loading.py", line 22, in import_string
    raise ImportError('Module "%s" does not define a "%s" attribute/class' % (
ImportError: Module "django.contrib.auth.hashers" does not define a "ScryptPasswordHasher" attribute/class
"POST /core/api/register-customer/ HTTP/1.1" 500 126028
/Users/bedeabbe/Desktop/projects/python/project_h_backend/project_h_core/auth_and_registration_views/register_views.py changed, reloading.
Watching for file changes with StatReloader
About to save user 
{'mobile_number': '0557881327', 'first_name': 'Jake', 'last_name': 'Banky', 'email': 'jake.banky@gmail.com', 'gender': 'm', 'address': 'Fillin Street 229', 'password': 'jake1234', 'dob': '2001-04-29'}
<built-in method today of type object at 0x10460dd38>
image is 
About to save customer details 
2024040416
Picture not there 
Customer saved 
"POST /core/api/register-customer/ HTTP/1.1" 202 857
/Users/bedeabbe/Desktop/projects/python/project_h_backend/project_h_core/auth_and_registration_views/register_views.py changed, reloading.
Watching for file changes with StatReloader
/Users/bedeabbe/Desktop/projects/python/project_h_backend/project_h/settings.py changed, reloading.
Watching for file changes with StatReloader
About to save user 
{'mobile_number': '0557881327', 'first_name': 'Jake', 'last_name': 'Banky', 'email': 'jake.banky@gmail.com', 'gender': 'm', 'address': 'Fillin Street 229', 'password': 'jake1234', 'dob': '2001-04-29'}
<built-in method today of type object at 0x102fddd38>
image is 
Internal Server Error: /core/api/register-customer/
Traceback (most recent call last):
  File "/Users/bedeabbe/Desktop/projects/python/venv/lib/python3.9/site-packages/django/utils/module_loading.py", line 20, in import_string
    return getattr(module, class_name)
AttributeError: module 'django.contrib.auth.hashers' has no attribute 'ScryptPasswordHasher'

The above exception was the direct cause of the following exception:

Traceback (most recent call last):
  File "/Users/bedeabbe/Desktop/projects/python/venv/lib/python3.9/site-packages/django/core/handlers/exception.py", line 47, in inner
    response = get_response(request)
  File "/Users/bedeabbe/Desktop/projects/python/venv/lib/python3.9/site-packages/django/core/handlers/base.py", line 181, in _get_response
    response = wrapped_callback(request, *callback_args, **callback_kwargs)
  File "/Users/bedeabbe/Desktop/projects/python/venv/lib/python3.9/site-packages/django/views/decorators/csrf.py", line 54, in wrapped_view
    return view_func(*args, **kwargs)
  File "/Users/bedeabbe/Desktop/projects/python/venv/lib/python3.9/site-packages/rest_framework/viewsets.py", line 125, in view
    return self.dispatch(request, *args, **kwargs)
  File "/Users/bedeabbe/Desktop/projects/python/venv/lib/python3.9/site-packages/rest_framework/views.py", line 509, in dispatch
    response = self.handle_exception(exc)
  File "/Users/bedeabbe/Desktop/projects/python/venv/lib/python3.9/site-packages/rest_framework/views.py", line 469, in handle_exception
    self.raise_uncaught_exception(exc)
  File "/Users/bedeabbe/Desktop/projects/python/venv/lib/python3.9/site-packages/rest_framework/views.py", line 480, in raise_uncaught_exception
    raise exc
  File "/Users/bedeabbe/Desktop/projects/python/venv/lib/python3.9/site-packages/rest_framework/views.py", line 506, in dispatch
    response = handler(request, *args, **kwargs)
  File "/Users/bedeabbe/Desktop/projects/python/project_h_backend/project_h_core/auth_and_registration_views/register_views.py", line 38, in create
    save_user = User.objects.create_user(
  File "/Users/bedeabbe/Desktop/projects/python/venv/lib/python3.9/site-packages/django/contrib/auth/models.py", line 146, in create_user
    return self._create_user(username, email, password, **extra_fields)
  File "/Users/bedeabbe/Desktop/projects/python/venv/lib/python3.9/site-packages/django/contrib/auth/models.py", line 139, in _create_user
    user.set_password(password)
  File "/Users/bedeabbe/Desktop/projects/python/venv/lib/python3.9/site-packages/django/contrib/auth/base_user.py", line 99, in set_password
    self.password = make_password(raw_password)
  File "/Users/bedeabbe/Desktop/projects/python/venv/lib/python3.9/site-packages/django/contrib/auth/hashers.py", line 80, in make_password
    hasher = get_hasher(hasher)
  File "/Users/bedeabbe/Desktop/projects/python/venv/lib/python3.9/site-packages/django/contrib/auth/hashers.py", line 121, in get_hasher
    return get_hashers()[0]
  File "/Users/bedeabbe/Desktop/projects/python/venv/lib/python3.9/site-packages/django/contrib/auth/hashers.py", line 89, in get_hashers
    hasher_cls = import_string(hasher_path)
  File "/Users/bedeabbe/Desktop/projects/python/venv/lib/python3.9/site-packages/django/utils/module_loading.py", line 22, in import_string
    raise ImportError('Module "%s" does not define a "%s" attribute/class' % (
ImportError: Module "django.contrib.auth.hashers" does not define a "ScryptPasswordHasher" attribute/class
"POST /core/api/register-customer/ HTTP/1.1" 500 126028
/Users/bedeabbe/Desktop/projects/python/project_h_backend/project_h_core/auth_and_registration_views/register_views.py changed, reloading.
Watching for file changes with StatReloader
About to save user 
{'mobile_number': '0557881327', 'first_name': 'Jake', 'last_name': 'Banky', 'email': 'jake.banky@gmail.com', 'gender': 'm', 'address': 'Fillin Street 229', 'password': 'jake1234', 'dob': '2001-04-29'}
<built-in method today of type object at 0x1026a9d38>
image is 
Internal Server Error: /core/api/register-customer/
Traceback (most recent call last):
  File "/Users/bedeabbe/Desktop/projects/python/venv/lib/python3.9/site-packages/django/utils/module_loading.py", line 20, in import_string
    return getattr(module, class_name)
AttributeError: module 'django.contrib.auth.hashers' has no attribute 'ScryptPasswordHasher'

The above exception was the direct cause of the following exception:

Traceback (most recent call last):
  File "/Users/bedeabbe/Desktop/projects/python/venv/lib/python3.9/site-packages/django/core/handlers/exception.py", line 47, in inner
    response = get_response(request)
  File "/Users/bedeabbe/Desktop/projects/python/venv/lib/python3.9/site-packages/django/core/handlers/base.py", line 181, in _get_response
    response = wrapped_callback(request, *callback_args, **callback_kwargs)
  File "/Users/bedeabbe/Desktop/projects/python/venv/lib/python3.9/site-packages/django/views/decorators/csrf.py", line 54, in wrapped_view
    return view_func(*args, **kwargs)
  File "/Users/bedeabbe/Desktop/projects/python/venv/lib/python3.9/site-packages/rest_framework/viewsets.py", line 125, in view
    return self.dispatch(request, *args, **kwargs)
  File "/Users/bedeabbe/Desktop/projects/python/venv/lib/python3.9/site-packages/rest_framework/views.py", line 509, in dispatch
    response = self.handle_exception(exc)
  File "/Users/bedeabbe/Desktop/projects/python/venv/lib/python3.9/site-packages/rest_framework/views.py", line 469, in handle_exception
    self.raise_uncaught_exception(exc)
  File "/Users/bedeabbe/Desktop/projects/python/venv/lib/python3.9/site-packages/rest_framework/views.py", line 480, in raise_uncaught_exception
    raise exc
  File "/Users/bedeabbe/Desktop/projects/python/venv/lib/python3.9/site-packages/rest_framework/views.py", line 506, in dispatch
    response = handler(request, *args, **kwargs)
  File "/Users/bedeabbe/Desktop/projects/python/project_h_backend/project_h_core/auth_and_registration_views/register_views.py", line 49, in create
    password=make_password(password)
  File "/Users/bedeabbe/Desktop/projects/python/venv/lib/python3.9/site-packages/django/contrib/auth/hashers.py", line 80, in make_password
    hasher = get_hasher(hasher)
  File "/Users/bedeabbe/Desktop/projects/python/venv/lib/python3.9/site-packages/django/contrib/auth/hashers.py", line 121, in get_hasher
    return get_hashers()[0]
  File "/Users/bedeabbe/Desktop/projects/python/venv/lib/python3.9/site-packages/django/contrib/auth/hashers.py", line 89, in get_hashers
    hasher_cls = import_string(hasher_path)
  File "/Users/bedeabbe/Desktop/projects/python/venv/lib/python3.9/site-packages/django/utils/module_loading.py", line 22, in import_string
    raise ImportError('Module "%s" does not define a "%s" attribute/class' % (
ImportError: Module "django.contrib.auth.hashers" does not define a "ScryptPasswordHasher" attribute/class
"POST /core/api/register-customer/ HTTP/1.1" 500 112548
/Users/bedeabbe/Desktop/projects/python/project_h_backend/project_h_core/auth_and_registration_views/register_views.py changed, reloading.
Watching for file changes with StatReloader
About to save user 
{'mobile_number': '0557881327', 'first_name': 'Jake', 'last_name': 'Banky', 'email': 'jake.banky@gmail.com', 'gender': 'm', 'address': 'Fillin Street 229', 'password': 'jake1234', 'dob': '2001-04-29'}
<built-in method today of type object at 0x1051b1d38>
image is 
Internal Server Error: /core/api/register-customer/
Traceback (most recent call last):
  File "/Users/bedeabbe/Desktop/projects/python/venv/lib/python3.9/site-packages/django/utils/module_loading.py", line 20, in import_string
    return getattr(module, class_name)
AttributeError: module 'django.contrib.auth.hashers' has no attribute 'ScryptPasswordHasher'

The above exception was the direct cause of the following exception:

Traceback (most recent call last):
  File "/Users/bedeabbe/Desktop/projects/python/venv/lib/python3.9/site-packages/django/core/handlers/exception.py", line 47, in inner
    response = get_response(request)
  File "/Users/bedeabbe/Desktop/projects/python/venv/lib/python3.9/site-packages/django/core/handlers/base.py", line 181, in _get_response
    response = wrapped_callback(request, *callback_args, **callback_kwargs)
  File "/Users/bedeabbe/Desktop/projects/python/venv/lib/python3.9/site-packages/django/views/decorators/csrf.py", line 54, in wrapped_view
    return view_func(*args, **kwargs)
  File "/Users/bedeabbe/Desktop/projects/python/venv/lib/python3.9/site-packages/rest_framework/viewsets.py", line 125, in view
    return self.dispatch(request, *args, **kwargs)
  File "/Users/bedeabbe/Desktop/projects/python/venv/lib/python3.9/site-packages/rest_framework/views.py", line 509, in dispatch
    response = self.handle_exception(exc)
  File "/Users/bedeabbe/Desktop/projects/python/venv/lib/python3.9/site-packages/rest_framework/views.py", line 469, in handle_exception
    self.raise_uncaught_exception(exc)
  File "/Users/bedeabbe/Desktop/projects/python/venv/lib/python3.9/site-packages/rest_framework/views.py", line 480, in raise_uncaught_exception
    raise exc
  File "/Users/bedeabbe/Desktop/projects/python/venv/lib/python3.9/site-packages/rest_framework/views.py", line 506, in dispatch
    response = handler(request, *args, **kwargs)
  File "/Users/bedeabbe/Desktop/projects/python/project_h_backend/project_h_core/auth_and_registration_views/register_views.py", line 49, in create
    password=make_password(password)
  File "/Users/bedeabbe/Desktop/projects/python/venv/lib/python3.9/site-packages/django/contrib/auth/hashers.py", line 80, in make_password
    hasher = get_hasher(hasher)
  File "/Users/bedeabbe/Desktop/projects/python/venv/lib/python3.9/site-packages/django/contrib/auth/hashers.py", line 121, in get_hasher
    return get_hashers()[0]
  File "/Users/bedeabbe/Desktop/projects/python/venv/lib/python3.9/site-packages/django/contrib/auth/hashers.py", line 89, in get_hashers
    hasher_cls = import_string(hasher_path)
  File "/Users/bedeabbe/Desktop/projects/python/venv/lib/python3.9/site-packages/django/utils/module_loading.py", line 22, in import_string
    raise ImportError('Module "%s" does not define a "%s" attribute/class' % (
ImportError: Module "django.contrib.auth.hashers" does not define a "ScryptPasswordHasher" attribute/class
"POST /core/api/register-customer/ HTTP/1.1" 500 112548
About to save user 
{'mobile_number': '0557881327', 'first_name': 'Jake', 'last_name': 'Banky', 'email': 'jake.banky@gmail.com', 'gender': 'm', 'address': 'Fillin Street 229', 'password': 'jake1234', 'dob': '2001-04-29'}
<built-in method today of type object at 0x1051b1d38>
image is 
Internal Server Error: /core/api/register-customer/
Traceback (most recent call last):
  File "/Users/bedeabbe/Desktop/projects/python/venv/lib/python3.9/site-packages/django/utils/module_loading.py", line 20, in import_string
    return getattr(module, class_name)
AttributeError: module 'django.contrib.auth.hashers' has no attribute 'ScryptPasswordHasher'

The above exception was the direct cause of the following exception:

Traceback (most recent call last):
  File "/Users/bedeabbe/Desktop/projects/python/venv/lib/python3.9/site-packages/django/core/handlers/exception.py", line 47, in inner
    response = get_response(request)
  File "/Users/bedeabbe/Desktop/projects/python/venv/lib/python3.9/site-packages/django/core/handlers/base.py", line 181, in _get_response
    response = wrapped_callback(request, *callback_args, **callback_kwargs)
  File "/Users/bedeabbe/Desktop/projects/python/venv/lib/python3.9/site-packages/django/views/decorators/csrf.py", line 54, in wrapped_view
    return view_func(*args, **kwargs)
  File "/Users/bedeabbe/Desktop/projects/python/venv/lib/python3.9/site-packages/rest_framework/viewsets.py", line 125, in view
    return self.dispatch(request, *args, **kwargs)
  File "/Users/bedeabbe/Desktop/projects/python/venv/lib/python3.9/site-packages/rest_framework/views.py", line 509, in dispatch
    response = self.handle_exception(exc)
  File "/Users/bedeabbe/Desktop/projects/python/venv/lib/python3.9/site-packages/rest_framework/views.py", line 469, in handle_exception
    self.raise_uncaught_exception(exc)
  File "/Users/bedeabbe/Desktop/projects/python/venv/lib/python3.9/site-packages/rest_framework/views.py", line 480, in raise_uncaught_exception
    raise exc
  File "/Users/bedeabbe/Desktop/projects/python/venv/lib/python3.9/site-packages/rest_framework/views.py", line 506, in dispatch
    response = handler(request, *args, **kwargs)
  File "/Users/bedeabbe/Desktop/projects/python/project_h_backend/project_h_core/auth_and_registration_views/register_views.py", line 49, in create
    password=make_password(password)
  File "/Users/bedeabbe/Desktop/projects/python/venv/lib/python3.9/site-packages/django/contrib/auth/hashers.py", line 80, in make_password
    hasher = get_hasher(hasher)
  File "/Users/bedeabbe/Desktop/projects/python/venv/lib/python3.9/site-packages/django/contrib/auth/hashers.py", line 121, in get_hasher
    return get_hashers()[0]
  File "/Users/bedeabbe/Desktop/projects/python/venv/lib/python3.9/site-packages/django/contrib/auth/hashers.py", line 89, in get_hashers
    hasher_cls = import_string(hasher_path)
  File "/Users/bedeabbe/Desktop/projects/python/venv/lib/python3.9/site-packages/django/utils/module_loading.py", line 22, in import_string
    raise ImportError('Module "%s" does not define a "%s" attribute/class' % (
ImportError: Module "django.contrib.auth.hashers" does not define a "ScryptPasswordHasher" attribute/class
"POST /core/api/register-customer/ HTTP/1.1" 500 112548
/Users/bedeabbe/Desktop/projects/python/project_h_backend/project_h/settings.py changed, reloading.
Watching for file changes with StatReloader
/Users/bedeabbe/Desktop/projects/python/project_h_backend/project_h/settings.py changed, reloading.
Watching for file changes with StatReloader
About to save user 
{'mobile_number': '0557881327', 'first_name': 'Jake', 'last_name': 'Banky', 'email': 'jake.banky@gmail.com', 'gender': 'm', 'address': 'Fillin Street 229', 'password': 'jake1234', 'dob': '2001-04-29'}
<built-in method today of type object at 0x10095dd38>
image is 
Internal Server Error: /core/api/register-customer/
Traceback (most recent call last):
  File "/Users/bedeabbe/Desktop/projects/python/venv/lib/python3.9/site-packages/django/utils/module_loading.py", line 20, in import_string
    return getattr(module, class_name)
AttributeError: module 'django.contrib.auth.hashers' has no attribute 'ScryptPasswordHasher'

The above exception was the direct cause of the following exception:

Traceback (most recent call last):
  File "/Users/bedeabbe/Desktop/projects/python/venv/lib/python3.9/site-packages/django/core/handlers/exception.py", line 47, in inner
    response = get_response(request)
  File "/Users/bedeabbe/Desktop/projects/python/venv/lib/python3.9/site-packages/django/core/handlers/base.py", line 181, in _get_response
    response = wrapped_callback(request, *callback_args, **callback_kwargs)
  File "/Users/bedeabbe/Desktop/projects/python/venv/lib/python3.9/site-packages/django/views/decorators/csrf.py", line 54, in wrapped_view
    return view_func(*args, **kwargs)
  File "/Users/bedeabbe/Desktop/projects/python/venv/lib/python3.9/site-packages/rest_framework/viewsets.py", line 125, in view
    return self.dispatch(request, *args, **kwargs)
  File "/Users/bedeabbe/Desktop/projects/python/venv/lib/python3.9/site-packages/rest_framework/views.py", line 509, in dispatch
    response = self.handle_exception(exc)
  File "/Users/bedeabbe/Desktop/projects/python/venv/lib/python3.9/site-packages/rest_framework/views.py", line 469, in handle_exception
    self.raise_uncaught_exception(exc)
  File "/Users/bedeabbe/Desktop/projects/python/venv/lib/python3.9/site-packages/rest_framework/views.py", line 480, in raise_uncaught_exception
    raise exc
  File "/Users/bedeabbe/Desktop/projects/python/venv/lib/python3.9/site-packages/rest_framework/views.py", line 506, in dispatch
    response = handler(request, *args, **kwargs)
  File "/Users/bedeabbe/Desktop/projects/python/project_h_backend/project_h_core/auth_and_registration_views/register_views.py", line 49, in create
    password=make_password(password)
  File "/Users/bedeabbe/Desktop/projects/python/venv/lib/python3.9/site-packages/django/contrib/auth/hashers.py", line 80, in make_password
    hasher = get_hasher(hasher)
  File "/Users/bedeabbe/Desktop/projects/python/venv/lib/python3.9/site-packages/django/contrib/auth/hashers.py", line 121, in get_hasher
    return get_hashers()[0]
  File "/Users/bedeabbe/Desktop/projects/python/venv/lib/python3.9/site-packages/django/contrib/auth/hashers.py", line 89, in get_hashers
    hasher_cls = import_string(hasher_path)
  File "/Users/bedeabbe/Desktop/projects/python/venv/lib/python3.9/site-packages/django/utils/module_loading.py", line 22, in import_string
    raise ImportError('Module "%s" does not define a "%s" attribute/class' % (
ImportError: Module "django.contrib.auth.hashers" does not define a "ScryptPasswordHasher" attribute/class
"POST /core/api/register-customer/ HTTP/1.1" 500 112548
/Users/bedeabbe/Desktop/projects/python/project_h_backend/project_h_core/auth_and_registration_views/register_views.py changed, reloading.
Watching for file changes with StatReloader
About to save user 
{'mobile_number': '0557881327', 'first_name': 'Jake', 'last_name': 'Banky', 'email': 'jake.banky@gmail.com', 'gender': 'm', 'address': 'Fillin Street 229', 'password': 'jake1234', 'dob': '2001-04-29'}
<built-in method today of type object at 0x104b41d38>
image is 
Internal Server Error: /core/api/register-customer/
Traceback (most recent call last):
  File "/Users/bedeabbe/Desktop/projects/python/venv/lib/python3.9/site-packages/django/utils/module_loading.py", line 20, in import_string
    return getattr(module, class_name)
AttributeError: module 'django.contrib.auth.hashers' has no attribute 'ScryptPasswordHasher'

The above exception was the direct cause of the following exception:

Traceback (most recent call last):
  File "/Users/bedeabbe/Desktop/projects/python/venv/lib/python3.9/site-packages/django/core/handlers/exception.py", line 47, in inner
    response = get_response(request)
  File "/Users/bedeabbe/Desktop/projects/python/venv/lib/python3.9/site-packages/django/core/handlers/base.py", line 181, in _get_response
    response = wrapped_callback(request, *callback_args, **callback_kwargs)
  File "/Users/bedeabbe/Desktop/projects/python/venv/lib/python3.9/site-packages/django/views/decorators/csrf.py", line 54, in wrapped_view
    return view_func(*args, **kwargs)
  File "/Users/bedeabbe/Desktop/projects/python/venv/lib/python3.9/site-packages/rest_framework/viewsets.py", line 125, in view
    return self.dispatch(request, *args, **kwargs)
  File "/Users/bedeabbe/Desktop/projects/python/venv/lib/python3.9/site-packages/rest_framework/views.py", line 509, in dispatch
    response = self.handle_exception(exc)
  File "/Users/bedeabbe/Desktop/projects/python/venv/lib/python3.9/site-packages/rest_framework/views.py", line 469, in handle_exception
    self.raise_uncaught_exception(exc)
  File "/Users/bedeabbe/Desktop/projects/python/venv/lib/python3.9/site-packages/rest_framework/views.py", line 480, in raise_uncaught_exception
    raise exc
  File "/Users/bedeabbe/Desktop/projects/python/venv/lib/python3.9/site-packages/rest_framework/views.py", line 506, in dispatch
    response = handler(request, *args, **kwargs)
  File "/Users/bedeabbe/Desktop/projects/python/project_h_backend/project_h_core/auth_and_registration_views/register_views.py", line 49, in create
    password=make_password(password)
  File "/Users/bedeabbe/Desktop/projects/python/venv/lib/python3.9/site-packages/django/contrib/auth/hashers.py", line 80, in make_password
    hasher = get_hasher(hasher)
  File "/Users/bedeabbe/Desktop/projects/python/venv/lib/python3.9/site-packages/django/contrib/auth/hashers.py", line 121, in get_hasher
    return get_hashers()[0]
  File "/Users/bedeabbe/Desktop/projects/python/venv/lib/python3.9/site-packages/django/contrib/auth/hashers.py", line 89, in get_hashers
    hasher_cls = import_string(hasher_path)
  File "/Users/bedeabbe/Desktop/projects/python/venv/lib/python3.9/site-packages/django/utils/module_loading.py", line 22, in import_string
    raise ImportError('Module "%s" does not define a "%s" attribute/class' % (
ImportError: Module "django.contrib.auth.hashers" does not define a "ScryptPasswordHasher" attribute/class
"POST /core/api/register-customer/ HTTP/1.1" 500 112548
Watching for file changes with StatReloader
About to save user 
{'mobile_number': '0557881327', 'first_name': 'Jake', 'last_name': 'Banky', 'email': 'jake.banky@gmail.com', 'gender': 'm', 'address': 'Fillin Street 229', 'password': 'jake1234', 'dob': '2001-04-29'}
<built-in method today of type object at 0x104a81d38>
image is 
Internal Server Error: /core/api/register-customer/
Traceback (most recent call last):
  File "/Users/bedeabbe/Desktop/projects/python/venv/lib/python3.9/site-packages/django/utils/module_loading.py", line 20, in import_string
    return getattr(module, class_name)
AttributeError: module 'django.contrib.auth.hashers' has no attribute 'ScryptPasswordHasher'

The above exception was the direct cause of the following exception:

Traceback (most recent call last):
  File "/Users/bedeabbe/Desktop/projects/python/venv/lib/python3.9/site-packages/django/core/handlers/exception.py", line 47, in inner
    response = get_response(request)
  File "/Users/bedeabbe/Desktop/projects/python/venv/lib/python3.9/site-packages/django/core/handlers/base.py", line 181, in _get_response
    response = wrapped_callback(request, *callback_args, **callback_kwargs)
  File "/Users/bedeabbe/Desktop/projects/python/venv/lib/python3.9/site-packages/django/views/decorators/csrf.py", line 54, in wrapped_view
    return view_func(*args, **kwargs)
  File "/Users/bedeabbe/Desktop/projects/python/venv/lib/python3.9/site-packages/rest_framework/viewsets.py", line 125, in view
    return self.dispatch(request, *args, **kwargs)
  File "/Users/bedeabbe/Desktop/projects/python/venv/lib/python3.9/site-packages/rest_framework/views.py", line 509, in dispatch
    response = self.handle_exception(exc)
  File "/Users/bedeabbe/Desktop/projects/python/venv/lib/python3.9/site-packages/rest_framework/views.py", line 469, in handle_exception
    self.raise_uncaught_exception(exc)
  File "/Users/bedeabbe/Desktop/projects/python/venv/lib/python3.9/site-packages/rest_framework/views.py", line 480, in raise_uncaught_exception
    raise exc
  File "/Users/bedeabbe/Desktop/projects/python/venv/lib/python3.9/site-packages/rest_framework/views.py", line 506, in dispatch
    response = handler(request, *args, **kwargs)
  File "/Users/bedeabbe/Desktop/projects/python/project_h_backend/project_h_core/auth_and_registration_views/register_views.py", line 49, in create
    password=make_password(password)
  File "/Users/bedeabbe/Desktop/projects/python/venv/lib/python3.9/site-packages/django/contrib/auth/hashers.py", line 80, in make_password
    hasher = get_hasher(hasher)
  File "/Users/bedeabbe/Desktop/projects/python/venv/lib/python3.9/site-packages/django/contrib/auth/hashers.py", line 121, in get_hasher
    return get_hashers()[0]
  File "/Users/bedeabbe/Desktop/projects/python/venv/lib/python3.9/site-packages/django/contrib/auth/hashers.py", line 89, in get_hashers
    hasher_cls = import_string(hasher_path)
  File "/Users/bedeabbe/Desktop/projects/python/venv/lib/python3.9/site-packages/django/utils/module_loading.py", line 22, in import_string
    raise ImportError('Module "%s" does not define a "%s" attribute/class' % (
ImportError: Module "django.contrib.auth.hashers" does not define a "ScryptPasswordHasher" attribute/class
"POST /core/api/register-customer/ HTTP/1.1" 500 112548
About to save user 
{'mobile_number': '0557881327', 'first_name': 'Jake', 'last_name': 'Banky', 'email': 'jake.banky@gmail.com', 'gender': 'm', 'address': 'Fillin Street 229', 'password': 'jake1234', 'dob': '2001-04-29'}
<built-in method today of type object at 0x104a81d38>
image is 
Internal Server Error: /core/api/register-customer/
Traceback (most recent call last):
  File "/Users/bedeabbe/Desktop/projects/python/venv/lib/python3.9/site-packages/django/utils/module_loading.py", line 20, in import_string
    return getattr(module, class_name)
AttributeError: module 'django.contrib.auth.hashers' has no attribute 'ScryptPasswordHasher'

The above exception was the direct cause of the following exception:

Traceback (most recent call last):
  File "/Users/bedeabbe/Desktop/projects/python/venv/lib/python3.9/site-packages/django/core/handlers/exception.py", line 47, in inner
    response = get_response(request)
  File "/Users/bedeabbe/Desktop/projects/python/venv/lib/python3.9/site-packages/django/core/handlers/base.py", line 181, in _get_response
    response = wrapped_callback(request, *callback_args, **callback_kwargs)
  File "/Users/bedeabbe/Desktop/projects/python/venv/lib/python3.9/site-packages/django/views/decorators/csrf.py", line 54, in wrapped_view
    return view_func(*args, **kwargs)
  File "/Users/bedeabbe/Desktop/projects/python/venv/lib/python3.9/site-packages/rest_framework/viewsets.py", line 125, in view
    return self.dispatch(request, *args, **kwargs)
  File "/Users/bedeabbe/Desktop/projects/python/venv/lib/python3.9/site-packages/rest_framework/views.py", line 509, in dispatch
    response = self.handle_exception(exc)
  File "/Users/bedeabbe/Desktop/projects/python/venv/lib/python3.9/site-packages/rest_framework/views.py", line 469, in handle_exception
    self.raise_uncaught_exception(exc)
  File "/Users/bedeabbe/Desktop/projects/python/venv/lib/python3.9/site-packages/rest_framework/views.py", line 480, in raise_uncaught_exception
    raise exc
  File "/Users/bedeabbe/Desktop/projects/python/venv/lib/python3.9/site-packages/rest_framework/views.py", line 506, in dispatch
    response = handler(request, *args, **kwargs)
  File "/Users/bedeabbe/Desktop/projects/python/project_h_backend/project_h_core/auth_and_registration_views/register_views.py", line 49, in create
    password=make_password(password)
  File "/Users/bedeabbe/Desktop/projects/python/venv/lib/python3.9/site-packages/django/contrib/auth/hashers.py", line 80, in make_password
    hasher = get_hasher(hasher)
  File "/Users/bedeabbe/Desktop/projects/python/venv/lib/python3.9/site-packages/django/contrib/auth/hashers.py", line 121, in get_hasher
    return get_hashers()[0]
  File "/Users/bedeabbe/Desktop/projects/python/venv/lib/python3.9/site-packages/django/contrib/auth/hashers.py", line 89, in get_hashers
    hasher_cls = import_string(hasher_path)
  File "/Users/bedeabbe/Desktop/projects/python/venv/lib/python3.9/site-packages/django/utils/module_loading.py", line 22, in import_string
    raise ImportError('Module "%s" does not define a "%s" attribute/class' % (
ImportError: Module "django.contrib.auth.hashers" does not define a "ScryptPasswordHasher" attribute/class
"POST /core/api/register-customer/ HTTP/1.1" 500 112548
/Users/bedeabbe/Desktop/projects/python/project_h_backend/project_h/settings.py changed, reloading.
Watching for file changes with StatReloader
/Users/bedeabbe/Desktop/projects/python/project_h_backend/project_h/settings.py changed, reloading.
Watching for file changes with StatReloader
About to save user 
{'mobile_number': '0557881327', 'first_name': 'Jake', 'last_name': 'Banky', 'email': 'jake.banky@gmail.com', 'gender': 'm', 'address': 'Fillin Street 229', 'password': 'jake1234', 'dob': '2001-04-29'}
<built-in method today of type object at 0x100c91d38>
image is 
Internal Server Error: /core/api/register-customer/
Traceback (most recent call last):
  File "/Users/bedeabbe/Desktop/projects/python/venv/lib/python3.9/site-packages/django/utils/module_loading.py", line 20, in import_string
    return getattr(module, class_name)
AttributeError: module 'django.contrib.auth.hashers' has no attribute 'ScryptPasswordHasher'

The above exception was the direct cause of the following exception:

Traceback (most recent call last):
  File "/Users/bedeabbe/Desktop/projects/python/venv/lib/python3.9/site-packages/django/core/handlers/exception.py", line 47, in inner
    response = get_response(request)
  File "/Users/bedeabbe/Desktop/projects/python/venv/lib/python3.9/site-packages/django/core/handlers/base.py", line 181, in _get_response
    response = wrapped_callback(request, *callback_args, **callback_kwargs)
  File "/Users/bedeabbe/Desktop/projects/python/venv/lib/python3.9/site-packages/django/views/decorators/csrf.py", line 54, in wrapped_view
    return view_func(*args, **kwargs)
  File "/Users/bedeabbe/Desktop/projects/python/venv/lib/python3.9/site-packages/rest_framework/viewsets.py", line 125, in view
    return self.dispatch(request, *args, **kwargs)
  File "/Users/bedeabbe/Desktop/projects/python/venv/lib/python3.9/site-packages/rest_framework/views.py", line 509, in dispatch
    response = self.handle_exception(exc)
  File "/Users/bedeabbe/Desktop/projects/python/venv/lib/python3.9/site-packages/rest_framework/views.py", line 469, in handle_exception
    self.raise_uncaught_exception(exc)
  File "/Users/bedeabbe/Desktop/projects/python/venv/lib/python3.9/site-packages/rest_framework/views.py", line 480, in raise_uncaught_exception
    raise exc
  File "/Users/bedeabbe/Desktop/projects/python/venv/lib/python3.9/site-packages/rest_framework/views.py", line 506, in dispatch
    response = handler(request, *args, **kwargs)
  File "/Users/bedeabbe/Desktop/projects/python/project_h_backend/project_h_core/auth_and_registration_views/register_views.py", line 49, in create
    password=make_password(password)
  File "/Users/bedeabbe/Desktop/projects/python/venv/lib/python3.9/site-packages/django/contrib/auth/hashers.py", line 80, in make_password
    hasher = get_hasher(hasher)
  File "/Users/bedeabbe/Desktop/projects/python/venv/lib/python3.9/site-packages/django/contrib/auth/hashers.py", line 121, in get_hasher
    return get_hashers()[0]
  File "/Users/bedeabbe/Desktop/projects/python/venv/lib/python3.9/site-packages/django/contrib/auth/hashers.py", line 89, in get_hashers
    hasher_cls = import_string(hasher_path)
  File "/Users/bedeabbe/Desktop/projects/python/venv/lib/python3.9/site-packages/django/utils/module_loading.py", line 22, in import_string
    raise ImportError('Module "%s" does not define a "%s" attribute/class' % (
ImportError: Module "django.contrib.auth.hashers" does not define a "ScryptPasswordHasher" attribute/class
"POST /core/api/register-customer/ HTTP/1.1" 500 112548
/Users/bedeabbe/Desktop/projects/python/project_h_backend/project_h_core/auth_and_registration_views/register_views.py changed, reloading.
Watching for file changes with StatReloader
About to save user 
{'mobile_number': '0557881327', 'first_name': 'Jake', 'last_name': 'Banky', 'email': 'jake.banky@gmail.com', 'gender': 'm', 'address': 'Fillin Street 229', 'password': 'jake1234', 'dob': '2001-04-29'}
<built-in method today of type object at 0x103181d38>
image is 
Internal Server Error: /core/api/register-customer/
Traceback (most recent call last):
  File "/Users/bedeabbe/Desktop/projects/python/venv/lib/python3.9/site-packages/django/utils/module_loading.py", line 20, in import_string
    return getattr(module, class_name)
AttributeError: module 'django.contrib.auth.hashers' has no attribute 'ScryptPasswordHasher'

The above exception was the direct cause of the following exception:

Traceback (most recent call last):
  File "/Users/bedeabbe/Desktop/projects/python/venv/lib/python3.9/site-packages/django/core/handlers/exception.py", line 47, in inner
    response = get_response(request)
  File "/Users/bedeabbe/Desktop/projects/python/venv/lib/python3.9/site-packages/django/core/handlers/base.py", line 181, in _get_response
    response = wrapped_callback(request, *callback_args, **callback_kwargs)
  File "/Users/bedeabbe/Desktop/projects/python/venv/lib/python3.9/site-packages/django/views/decorators/csrf.py", line 54, in wrapped_view
    return view_func(*args, **kwargs)
  File "/Users/bedeabbe/Desktop/projects/python/venv/lib/python3.9/site-packages/rest_framework/viewsets.py", line 125, in view
    return self.dispatch(request, *args, **kwargs)
  File "/Users/bedeabbe/Desktop/projects/python/venv/lib/python3.9/site-packages/rest_framework/views.py", line 509, in dispatch
    response = self.handle_exception(exc)
  File "/Users/bedeabbe/Desktop/projects/python/venv/lib/python3.9/site-packages/rest_framework/views.py", line 469, in handle_exception
    self.raise_uncaught_exception(exc)
  File "/Users/bedeabbe/Desktop/projects/python/venv/lib/python3.9/site-packages/rest_framework/views.py", line 480, in raise_uncaught_exception
    raise exc
  File "/Users/bedeabbe/Desktop/projects/python/venv/lib/python3.9/site-packages/rest_framework/views.py", line 506, in dispatch
    response = handler(request, *args, **kwargs)
  File "/Users/bedeabbe/Desktop/projects/python/project_h_backend/project_h_core/auth_and_registration_views/register_views.py", line 49, in create
    password=make_password(password)
  File "/Users/bedeabbe/Desktop/projects/python/venv/lib/python3.9/site-packages/django/contrib/auth/hashers.py", line 80, in make_password
    hasher = get_hasher(hasher)
  File "/Users/bedeabbe/Desktop/projects/python/venv/lib/python3.9/site-packages/django/contrib/auth/hashers.py", line 121, in get_hasher
    return get_hashers()[0]
  File "/Users/bedeabbe/Desktop/projects/python/venv/lib/python3.9/site-packages/django/contrib/auth/hashers.py", line 89, in get_hashers
    hasher_cls = import_string(hasher_path)
  File "/Users/bedeabbe/Desktop/projects/python/venv/lib/python3.9/site-packages/django/utils/module_loading.py", line 22, in import_string
    raise ImportError('Module "%s" does not define a "%s" attribute/class' % (
ImportError: Module "django.contrib.auth.hashers" does not define a "ScryptPasswordHasher" attribute/class
"POST /core/api/register-customer/ HTTP/1.1" 500 112548
/Users/bedeabbe/Desktop/projects/python/project_h_backend/project_h_core/auth_and_registration_views/register_views.py changed, reloading.
Watching for file changes with StatReloader
/Users/bedeabbe/Desktop/projects/python/project_h_backend/project_h_core/auth_and_registration_views/register_views.py changed, reloading.
Watching for file changes with StatReloader
About to save user 
{'mobile_number': '0557881327', 'first_name': 'Jake', 'last_name': 'Banky', 'email': 'jake.banky@gmail.com', 'gender': 'm', 'address': 'Fillin Street 229', 'password': 'jake1234', 'dob': '2001-04-29'}
<built-in method today of type object at 0x10257dd38>
image is 
Internal Server Error: /core/api/register-customer/
Traceback (most recent call last):
  File "/Users/bedeabbe/Desktop/projects/python/venv/lib/python3.9/site-packages/django/utils/module_loading.py", line 20, in import_string
    return getattr(module, class_name)
AttributeError: module 'django.contrib.auth.hashers' has no attribute 'ScryptPasswordHasher'

The above exception was the direct cause of the following exception:

Traceback (most recent call last):
  File "/Users/bedeabbe/Desktop/projects/python/venv/lib/python3.9/site-packages/django/core/handlers/exception.py", line 47, in inner
    response = get_response(request)
  File "/Users/bedeabbe/Desktop/projects/python/venv/lib/python3.9/site-packages/django/core/handlers/base.py", line 181, in _get_response
    response = wrapped_callback(request, *callback_args, **callback_kwargs)
  File "/Users/bedeabbe/Desktop/projects/python/venv/lib/python3.9/site-packages/django/views/decorators/csrf.py", line 54, in wrapped_view
    return view_func(*args, **kwargs)
  File "/Users/bedeabbe/Desktop/projects/python/venv/lib/python3.9/site-packages/rest_framework/viewsets.py", line 125, in view
    return self.dispatch(request, *args, **kwargs)
  File "/Users/bedeabbe/Desktop/projects/python/venv/lib/python3.9/site-packages/rest_framework/views.py", line 509, in dispatch
    response = self.handle_exception(exc)
  File "/Users/bedeabbe/Desktop/projects/python/venv/lib/python3.9/site-packages/rest_framework/views.py", line 469, in handle_exception
    self.raise_uncaught_exception(exc)
  File "/Users/bedeabbe/Desktop/projects/python/venv/lib/python3.9/site-packages/rest_framework/views.py", line 480, in raise_uncaught_exception
    raise exc
  File "/Users/bedeabbe/Desktop/projects/python/venv/lib/python3.9/site-packages/rest_framework/views.py", line 506, in dispatch
    response = handler(request, *args, **kwargs)
  File "/Users/bedeabbe/Desktop/projects/python/project_h_backend/project_h_core/auth_and_registration_views/register_views.py", line 53, in create
    save_user.set_password(password)
  File "/Users/bedeabbe/Desktop/projects/python/venv/lib/python3.9/site-packages/django/contrib/auth/base_user.py", line 99, in set_password
    self.password = make_password(raw_password)
  File "/Users/bedeabbe/Desktop/projects/python/venv/lib/python3.9/site-packages/django/contrib/auth/hashers.py", line 80, in make_password
    hasher = get_hasher(hasher)
  File "/Users/bedeabbe/Desktop/projects/python/venv/lib/python3.9/site-packages/django/contrib/auth/hashers.py", line 121, in get_hasher
    return get_hashers()[0]
  File "/Users/bedeabbe/Desktop/projects/python/venv/lib/python3.9/site-packages/django/contrib/auth/hashers.py", line 89, in get_hashers
    hasher_cls = import_string(hasher_path)
  File "/Users/bedeabbe/Desktop/projects/python/venv/lib/python3.9/site-packages/django/utils/module_loading.py", line 22, in import_string
    raise ImportError('Module "%s" does not define a "%s" attribute/class' % (
ImportError: Module "django.contrib.auth.hashers" does not define a "ScryptPasswordHasher" attribute/class
"POST /core/api/register-customer/ HTTP/1.1" 500 116337
/Users/bedeabbe/Desktop/projects/python/project_h_backend/project_h/settings.py changed, reloading.
Watching for file changes with StatReloader
/Users/bedeabbe/Desktop/projects/python/project_h_backend/project_h_core/auth_and_registration_views/register_views.py changed, reloading.
Watching for file changes with StatReloader
About to save user 
{'mobile_number': '0557881327', 'first_name': 'Jake', 'last_name': 'Banky', 'email': 'jake.banky@gmail.com', 'gender': 'm', 'address': 'Fillin Street 229', 'password': 'jake1234', 'dob': '2001-04-29'}
<built-in method today of type object at 0x1023f9d38>
image is 
Internal Server Error: /core/api/register-customer/
Traceback (most recent call last):
  File "/Users/bedeabbe/Desktop/projects/python/venv/lib/python3.9/site-packages/django/db/backends/utils.py", line 84, in _execute
    return self.cursor.execute(sql, params)
  File "/Users/bedeabbe/Desktop/projects/python/venv/lib/python3.9/site-packages/django/db/backends/mysql/base.py", line 73, in execute
    return self.cursor.execute(query, args)
  File "/Users/bedeabbe/Desktop/projects/python/venv/lib/python3.9/site-packages/pymysql/cursors.py", line 148, in execute
    result = self._query(query)
  File "/Users/bedeabbe/Desktop/projects/python/venv/lib/python3.9/site-packages/pymysql/cursors.py", line 310, in _query
    conn.query(q)
  File "/Users/bedeabbe/Desktop/projects/python/venv/lib/python3.9/site-packages/pymysql/connections.py", line 548, in query
    self._affected_rows = self._read_query_result(unbuffered=unbuffered)
  File "/Users/bedeabbe/Desktop/projects/python/venv/lib/python3.9/site-packages/pymysql/connections.py", line 775, in _read_query_result
    result.read()
  File "/Users/bedeabbe/Desktop/projects/python/venv/lib/python3.9/site-packages/pymysql/connections.py", line 1156, in read
    first_packet = self.connection._read_packet()
  File "/Users/bedeabbe/Desktop/projects/python/venv/lib/python3.9/site-packages/pymysql/connections.py", line 725, in _read_packet
    packet.raise_for_error()
  File "/Users/bedeabbe/Desktop/projects/python/venv/lib/python3.9/site-packages/pymysql/protocol.py", line 221, in raise_for_error
    err.raise_mysql_exception(self._data)
  File "/Users/bedeabbe/Desktop/projects/python/venv/lib/python3.9/site-packages/pymysql/err.py", line 143, in raise_mysql_exception
    raise errorclass(errno, errval)
pymysql.err.IntegrityError: (1062, "Duplicate entry 'jake.banky' for key 'auth_user.username'")

The above exception was the direct cause of the following exception:

Traceback (most recent call last):
  File "/Users/bedeabbe/Desktop/projects/python/venv/lib/python3.9/site-packages/django/core/handlers/exception.py", line 47, in inner
    response = get_response(request)
  File "/Users/bedeabbe/Desktop/projects/python/venv/lib/python3.9/site-packages/django/core/handlers/base.py", line 181, in _get_response
    response = wrapped_callback(request, *callback_args, **callback_kwargs)
  File "/Users/bedeabbe/Desktop/projects/python/venv/lib/python3.9/site-packages/django/views/decorators/csrf.py", line 54, in wrapped_view
    return view_func(*args, **kwargs)
  File "/Users/bedeabbe/Desktop/projects/python/venv/lib/python3.9/site-packages/rest_framework/viewsets.py", line 125, in view
    return self.dispatch(request, *args, **kwargs)
  File "/Users/bedeabbe/Desktop/projects/python/venv/lib/python3.9/site-packages/rest_framework/views.py", line 509, in dispatch
    response = self.handle_exception(exc)
  File "/Users/bedeabbe/Desktop/projects/python/venv/lib/python3.9/site-packages/rest_framework/views.py", line 469, in handle_exception
    self.raise_uncaught_exception(exc)
  File "/Users/bedeabbe/Desktop/projects/python/venv/lib/python3.9/site-packages/rest_framework/views.py", line 480, in raise_uncaught_exception
    raise exc
  File "/Users/bedeabbe/Desktop/projects/python/venv/lib/python3.9/site-packages/rest_framework/views.py", line 506, in dispatch
    response = handler(request, *args, **kwargs)
  File "/Users/bedeabbe/Desktop/projects/python/project_h_backend/project_h_core/auth_and_registration_views/register_views.py", line 52, in create
    save_user.save()
  File "/Users/bedeabbe/Desktop/projects/python/venv/lib/python3.9/site-packages/django/contrib/auth/base_user.py", line 67, in save
    super().save(*args, **kwargs)
  File "/Users/bedeabbe/Desktop/projects/python/venv/lib/python3.9/site-packages/django/db/models/base.py", line 753, in save
    self.save_base(using=using, force_insert=force_insert,
  File "/Users/bedeabbe/Desktop/projects/python/venv/lib/python3.9/site-packages/django/db/models/base.py", line 790, in save_base
    updated = self._save_table(
  File "/Users/bedeabbe/Desktop/projects/python/venv/lib/python3.9/site-packages/django/db/models/base.py", line 895, in _save_table
    results = self._do_insert(cls._base_manager, using, fields, returning_fields, raw)
  File "/Users/bedeabbe/Desktop/projects/python/venv/lib/python3.9/site-packages/django/db/models/base.py", line 933, in _do_insert
    return manager._insert(
  File "/Users/bedeabbe/Desktop/projects/python/venv/lib/python3.9/site-packages/django/db/models/manager.py", line 85, in manager_method
    return getattr(self.get_queryset(), name)(*args, **kwargs)
  File "/Users/bedeabbe/Desktop/projects/python/venv/lib/python3.9/site-packages/django/db/models/query.py", line 1254, in _insert
    return query.get_compiler(using=using).execute_sql(returning_fields)
  File "/Users/bedeabbe/Desktop/projects/python/venv/lib/python3.9/site-packages/django/db/models/sql/compiler.py", line 1397, in execute_sql
    cursor.execute(sql, params)
  File "/Users/bedeabbe/Desktop/projects/python/venv/lib/python3.9/site-packages/django/db/backends/utils.py", line 98, in execute
    return super().execute(sql, params)
  File "/Users/bedeabbe/Desktop/projects/python/venv/lib/python3.9/site-packages/django/db/backends/utils.py", line 66, in execute
    return self._execute_with_wrappers(sql, params, many=False, executor=self._execute)
  File "/Users/bedeabbe/Desktop/projects/python/venv/lib/python3.9/site-packages/django/db/backends/utils.py", line 75, in _execute_with_wrappers
    return executor(sql, params, many, context)
  File "/Users/bedeabbe/Desktop/projects/python/venv/lib/python3.9/site-packages/django/db/backends/utils.py", line 84, in _execute
    return self.cursor.execute(sql, params)
  File "/Users/bedeabbe/Desktop/projects/python/venv/lib/python3.9/site-packages/django/db/utils.py", line 90, in __exit__
    raise dj_exc_value.with_traceback(traceback) from exc_value
  File "/Users/bedeabbe/Desktop/projects/python/venv/lib/python3.9/site-packages/django/db/backends/utils.py", line 84, in _execute
    return self.cursor.execute(sql, params)
  File "/Users/bedeabbe/Desktop/projects/python/venv/lib/python3.9/site-packages/django/db/backends/mysql/base.py", line 73, in execute
    return self.cursor.execute(query, args)
  File "/Users/bedeabbe/Desktop/projects/python/venv/lib/python3.9/site-packages/pymysql/cursors.py", line 148, in execute
    result = self._query(query)
  File "/Users/bedeabbe/Desktop/projects/python/venv/lib/python3.9/site-packages/pymysql/cursors.py", line 310, in _query
    conn.query(q)
  File "/Users/bedeabbe/Desktop/projects/python/venv/lib/python3.9/site-packages/pymysql/connections.py", line 548, in query
    self._affected_rows = self._read_query_result(unbuffered=unbuffered)
  File "/Users/bedeabbe/Desktop/projects/python/venv/lib/python3.9/site-packages/pymysql/connections.py", line 775, in _read_query_result
    result.read()
  File "/Users/bedeabbe/Desktop/projects/python/venv/lib/python3.9/site-packages/pymysql/connections.py", line 1156, in read
    first_packet = self.connection._read_packet()
  File "/Users/bedeabbe/Desktop/projects/python/venv/lib/python3.9/site-packages/pymysql/connections.py", line 725, in _read_packet
    packet.raise_for_error()
  File "/Users/bedeabbe/Desktop/projects/python/venv/lib/python3.9/site-packages/pymysql/protocol.py", line 221, in raise_for_error
    err.raise_mysql_exception(self._data)
  File "/Users/bedeabbe/Desktop/projects/python/venv/lib/python3.9/site-packages/pymysql/err.py", line 143, in raise_mysql_exception
    raise errorclass(errno, errval)
django.db.utils.IntegrityError: (1062, "Duplicate entry 'jake.banky' for key 'auth_user.username'")
"POST /core/api/register-customer/ HTTP/1.1" 500 243686
About to save user 
{'mobile_number': '0557881327', 'first_name': 'Jake', 'last_name': 'Banky', 'email': 'jake.banky@gmail.com', 'gender': 'm', 'address': 'Fillin Street 229', 'password': 'jake1234', 'dob': '2001-04-29'}
<built-in method today of type object at 0x1023f9d38>
image is 
About to save customer details 
2024040419
Picture not there 
Customer saved 
"POST /core/api/register-customer/ HTTP/1.1" 202 927
/Users/bedeabbe/Desktop/projects/python/project_h_backend/project_h_core/urls.py changed, reloading.
Watching for file changes with StatReloader
About to validate OTP
Internal Server Error: /core/api/authenticate/
Traceback (most recent call last):
  File "/Users/bedeabbe/Desktop/projects/python/venv/lib/python3.9/site-packages/django/core/handlers/exception.py", line 47, in inner
    response = get_response(request)
  File "/Users/bedeabbe/Desktop/projects/python/venv/lib/python3.9/site-packages/django/core/handlers/base.py", line 181, in _get_response
    response = wrapped_callback(request, *callback_args, **callback_kwargs)
  File "/Users/bedeabbe/Desktop/projects/python/venv/lib/python3.9/site-packages/django/views/decorators/csrf.py", line 54, in wrapped_view
    return view_func(*args, **kwargs)
  File "/Users/bedeabbe/Desktop/projects/python/venv/lib/python3.9/site-packages/rest_framework/viewsets.py", line 125, in view
    return self.dispatch(request, *args, **kwargs)
  File "/Users/bedeabbe/Desktop/projects/python/venv/lib/python3.9/site-packages/rest_framework/views.py", line 509, in dispatch
    response = self.handle_exception(exc)
  File "/Users/bedeabbe/Desktop/projects/python/venv/lib/python3.9/site-packages/rest_framework/views.py", line 469, in handle_exception
    self.raise_uncaught_exception(exc)
  File "/Users/bedeabbe/Desktop/projects/python/venv/lib/python3.9/site-packages/rest_framework/views.py", line 480, in raise_uncaught_exception
    raise exc
  File "/Users/bedeabbe/Desktop/projects/python/venv/lib/python3.9/site-packages/rest_framework/views.py", line 506, in dispatch
    response = handler(request, *args, **kwargs)
  File "/Users/bedeabbe/Desktop/projects/python/project_h_backend/project_h_core/auth_and_registration_views/authentication_view.py", line 27, in create
    logger.info(serializer.data['otp'])
KeyError: 'otp'
"POST /core/api/authenticate/ HTTP/1.1" 500 89034
/Users/bedeabbe/Desktop/projects/python/project_h_backend/project_h_core/auth_and_registration_views/authentication_view.py changed, reloading.
Watching for file changes with StatReloader
About to validate OTP
Internal Server Error: /core/api/authenticate/
Traceback (most recent call last):
  File "/Users/bedeabbe/Desktop/projects/python/venv/lib/python3.9/site-packages/django/core/handlers/exception.py", line 47, in inner
    response = get_response(request)
  File "/Users/bedeabbe/Desktop/projects/python/venv/lib/python3.9/site-packages/django/core/handlers/base.py", line 181, in _get_response
    response = wrapped_callback(request, *callback_args, **callback_kwargs)
  File "/Users/bedeabbe/Desktop/projects/python/venv/lib/python3.9/site-packages/django/views/decorators/csrf.py", line 54, in wrapped_view
    return view_func(*args, **kwargs)
  File "/Users/bedeabbe/Desktop/projects/python/venv/lib/python3.9/site-packages/rest_framework/viewsets.py", line 125, in view
    return self.dispatch(request, *args, **kwargs)
  File "/Users/bedeabbe/Desktop/projects/python/venv/lib/python3.9/site-packages/rest_framework/views.py", line 509, in dispatch
    response = self.handle_exception(exc)
  File "/Users/bedeabbe/Desktop/projects/python/venv/lib/python3.9/site-packages/rest_framework/views.py", line 469, in handle_exception
    self.raise_uncaught_exception(exc)
  File "/Users/bedeabbe/Desktop/projects/python/venv/lib/python3.9/site-packages/rest_framework/views.py", line 480, in raise_uncaught_exception
    raise exc
  File "/Users/bedeabbe/Desktop/projects/python/venv/lib/python3.9/site-packages/rest_framework/views.py", line 506, in dispatch
    response = handler(request, *args, **kwargs)
  File "/Users/bedeabbe/Desktop/projects/python/project_h_backend/project_h_core/auth_and_registration_views/authentication_view.py", line 29, in create
    user = User.objects.get(customers__mobile_number=serializer.data['username'])
  File "/Users/bedeabbe/Desktop/projects/python/venv/lib/python3.9/site-packages/django/db/models/manager.py", line 85, in manager_method
    return getattr(self.get_queryset(), name)(*args, **kwargs)
  File "/Users/bedeabbe/Desktop/projects/python/venv/lib/python3.9/site-packages/django/db/models/query.py", line 429, in get
    raise self.model.DoesNotExist(
django.contrib.auth.models.User.DoesNotExist: User matching query does not exist.
"POST /core/api/authenticate/ HTTP/1.1" 500 98315
/Users/bedeabbe/Desktop/projects/python/project_h_backend/project_h_core/auth_and_registration_views/authentication_view.py changed, reloading.
Watching for file changes with StatReloader
About to validate OTP
User details are 
jake.banky
Internal Server Error: /core/api/authenticate/
Traceback (most recent call last):
  File "/Users/bedeabbe/Desktop/projects/python/venv/lib/python3.9/site-packages/django/core/handlers/exception.py", line 47, in inner
    response = get_response(request)
  File "/Users/bedeabbe/Desktop/projects/python/venv/lib/python3.9/site-packages/django/core/handlers/base.py", line 181, in _get_response
    response = wrapped_callback(request, *callback_args, **callback_kwargs)
  File "/Users/bedeabbe/Desktop/projects/python/venv/lib/python3.9/site-packages/django/views/decorators/csrf.py", line 54, in wrapped_view
    return view_func(*args, **kwargs)
  File "/Users/bedeabbe/Desktop/projects/python/venv/lib/python3.9/site-packages/rest_framework/viewsets.py", line 125, in view
    return self.dispatch(request, *args, **kwargs)
  File "/Users/bedeabbe/Desktop/projects/python/venv/lib/python3.9/site-packages/rest_framework/views.py", line 509, in dispatch
    response = self.handle_exception(exc)
  File "/Users/bedeabbe/Desktop/projects/python/venv/lib/python3.9/site-packages/rest_framework/views.py", line 469, in handle_exception
    self.raise_uncaught_exception(exc)
  File "/Users/bedeabbe/Desktop/projects/python/venv/lib/python3.9/site-packages/rest_framework/views.py", line 480, in raise_uncaught_exception
    raise exc
  File "/Users/bedeabbe/Desktop/projects/python/venv/lib/python3.9/site-packages/rest_framework/views.py", line 506, in dispatch
    response = handler(request, *args, **kwargs)
  File "/Users/bedeabbe/Desktop/projects/python/project_h_backend/project_h_core/auth_and_registration_views/authentication_view.py", line 33, in create
    logger.info("Check password response is "+checkPasswordResp)
TypeError: can only concatenate str (not "bool") to str
"POST /core/api/authenticate/ HTTP/1.1" 500 89871
/Users/bedeabbe/Desktop/projects/python/project_h_backend/project_h_core/auth_and_registration_views/authentication_view.py changed, reloading.
Watching for file changes with StatReloader
About to validate OTP
User details are 
jake.banky
Check password response is 
True
Internal Server Error: /core/api/authenticate/
Traceback (most recent call last):
  File "/Users/bedeabbe/Desktop/projects/python/venv/lib/python3.9/site-packages/django/core/handlers/exception.py", line 47, in inner
    response = get_response(request)
  File "/Users/bedeabbe/Desktop/projects/python/venv/lib/python3.9/site-packages/django/core/handlers/base.py", line 204, in _get_response
    response = response.render()
  File "/Users/bedeabbe/Desktop/projects/python/venv/lib/python3.9/site-packages/django/template/response.py", line 105, in render
    self.content = self.rendered_content
  File "/Users/bedeabbe/Desktop/projects/python/venv/lib/python3.9/site-packages/rest_framework/response.py", line 70, in rendered_content
    ret = renderer.render(self.data, accepted_media_type, context)
  File "/Users/bedeabbe/Desktop/projects/python/venv/lib/python3.9/site-packages/rest_framework/renderers.py", line 100, in render
    ret = json.dumps(
  File "/Users/bedeabbe/Desktop/projects/python/venv/lib/python3.9/site-packages/rest_framework/utils/json.py", line 25, in dumps
    return json.dumps(*args, **kwargs)
  File "/Applications/Xcode.app/Contents/Developer/Library/Frameworks/Python3.framework/Versions/3.9/lib/python3.9/json/__init__.py", line 234, in dumps
    return cls(
  File "/Applications/Xcode.app/Contents/Developer/Library/Frameworks/Python3.framework/Versions/3.9/lib/python3.9/json/encoder.py", line 199, in encode
    chunks = self.iterencode(o, _one_shot=True)
  File "/Applications/Xcode.app/Contents/Developer/Library/Frameworks/Python3.framework/Versions/3.9/lib/python3.9/json/encoder.py", line 257, in iterencode
    return _iterencode(o, 0)
  File "/Users/bedeabbe/Desktop/projects/python/venv/lib/python3.9/site-packages/rest_framework/utils/encoders.py", line 67, in default
    return super().default(obj)
  File "/Applications/Xcode.app/Contents/Developer/Library/Frameworks/Python3.framework/Versions/3.9/lib/python3.9/json/encoder.py", line 179, in default
    raise TypeError(f'Object of type {o.__class__.__name__} '
TypeError: Object of type module is not JSON serializable
"POST /core/api/authenticate/ HTTP/1.1" 500 98093
/Users/bedeabbe/Desktop/projects/python/project_h_backend/project_h_core/auth_and_registration_views/authentication_view.py changed, reloading.
Watching for file changes with StatReloader
/Users/bedeabbe/Desktop/projects/python/project_h_backend/project_h_core/auth_and_registration_views/authentication_view.py changed, reloading.
Watching for file changes with StatReloader
/Users/bedeabbe/Desktop/projects/python/project_h_backend/project_h_core/auth_and_registration_views/authentication_view.py changed, reloading.
Watching for file changes with StatReloader
About to validate OTP
User details are 
jake.banky
Check password response is 
True
About to send response
Internal Server Error: /core/api/authenticate/
Traceback (most recent call last):
  File "/Users/bedeabbe/Desktop/projects/python/venv/lib/python3.9/site-packages/django/core/handlers/exception.py", line 47, in inner
    response = get_response(request)
  File "/Users/bedeabbe/Desktop/projects/python/venv/lib/python3.9/site-packages/django/core/handlers/base.py", line 204, in _get_response
    response = response.render()
  File "/Users/bedeabbe/Desktop/projects/python/venv/lib/python3.9/site-packages/django/template/response.py", line 105, in render
    self.content = self.rendered_content
  File "/Users/bedeabbe/Desktop/projects/python/venv/lib/python3.9/site-packages/rest_framework/response.py", line 70, in rendered_content
    ret = renderer.render(self.data, accepted_media_type, context)
  File "/Users/bedeabbe/Desktop/projects/python/venv/lib/python3.9/site-packages/rest_framework/renderers.py", line 100, in render
    ret = json.dumps(
  File "/Users/bedeabbe/Desktop/projects/python/venv/lib/python3.9/site-packages/rest_framework/utils/json.py", line 25, in dumps
    return json.dumps(*args, **kwargs)
  File "/Applications/Xcode.app/Contents/Developer/Library/Frameworks/Python3.framework/Versions/3.9/lib/python3.9/json/__init__.py", line 234, in dumps
    return cls(
  File "/Applications/Xcode.app/Contents/Developer/Library/Frameworks/Python3.framework/Versions/3.9/lib/python3.9/json/encoder.py", line 199, in encode
    chunks = self.iterencode(o, _one_shot=True)
  File "/Applications/Xcode.app/Contents/Developer/Library/Frameworks/Python3.framework/Versions/3.9/lib/python3.9/json/encoder.py", line 257, in iterencode
    return _iterencode(o, 0)
  File "/Users/bedeabbe/Desktop/projects/python/venv/lib/python3.9/site-packages/rest_framework/utils/encoders.py", line 67, in default
    return super().default(obj)
  File "/Applications/Xcode.app/Contents/Developer/Library/Frameworks/Python3.framework/Versions/3.9/lib/python3.9/json/encoder.py", line 179, in default
    raise TypeError(f'Object of type {o.__class__.__name__} '
TypeError: Object of type module is not JSON serializable
"POST /core/api/authenticate/ HTTP/1.1" 500 98093
/Users/bedeabbe/Desktop/projects/python/project_h_backend/project_h_core/auth_and_registration_views/authentication_view.py changed, reloading.
Watching for file changes with StatReloader
About to validate OTP
User details are 
jake.banky
Check password response is 
True
About to send response
Internal Server Error: /core/api/authenticate/
Traceback (most recent call last):
  File "/Users/bedeabbe/Desktop/projects/python/venv/lib/python3.9/site-packages/django/core/handlers/exception.py", line 47, in inner
    response = get_response(request)
  File "/Users/bedeabbe/Desktop/projects/python/venv/lib/python3.9/site-packages/django/core/handlers/base.py", line 204, in _get_response
    response = response.render()
  File "/Users/bedeabbe/Desktop/projects/python/venv/lib/python3.9/site-packages/django/template/response.py", line 105, in render
    self.content = self.rendered_content
  File "/Users/bedeabbe/Desktop/projects/python/venv/lib/python3.9/site-packages/rest_framework/response.py", line 70, in rendered_content
    ret = renderer.render(self.data, accepted_media_type, context)
  File "/Users/bedeabbe/Desktop/projects/python/venv/lib/python3.9/site-packages/rest_framework/renderers.py", line 100, in render
    ret = json.dumps(
  File "/Users/bedeabbe/Desktop/projects/python/venv/lib/python3.9/site-packages/rest_framework/utils/json.py", line 25, in dumps
    return json.dumps(*args, **kwargs)
  File "/Applications/Xcode.app/Contents/Developer/Library/Frameworks/Python3.framework/Versions/3.9/lib/python3.9/json/__init__.py", line 234, in dumps
    return cls(
  File "/Applications/Xcode.app/Contents/Developer/Library/Frameworks/Python3.framework/Versions/3.9/lib/python3.9/json/encoder.py", line 199, in encode
    chunks = self.iterencode(o, _one_shot=True)
  File "/Applications/Xcode.app/Contents/Developer/Library/Frameworks/Python3.framework/Versions/3.9/lib/python3.9/json/encoder.py", line 257, in iterencode
    return _iterencode(o, 0)
  File "/Users/bedeabbe/Desktop/projects/python/venv/lib/python3.9/site-packages/rest_framework/utils/encoders.py", line 67, in default
    return super().default(obj)
  File "/Applications/Xcode.app/Contents/Developer/Library/Frameworks/Python3.framework/Versions/3.9/lib/python3.9/json/encoder.py", line 179, in default
    raise TypeError(f'Object of type {o.__class__.__name__} '
TypeError: Object of type module is not JSON serializable
"POST /core/api/authenticate/ HTTP/1.1" 500 98357
/Users/bedeabbe/Desktop/projects/python/project_h_backend/project_h_core/auth_and_registration_views/authentication_view.py changed, reloading.
Watching for file changes with StatReloader
/Users/bedeabbe/Desktop/projects/python/project_h_backend/project_h_core/auth_and_registration_views/authentication_view.py changed, reloading.
Watching for file changes with StatReloader
About to validate OTP
User details are 
jake.banky
Check password response is 
True
About to send response
Internal Server Error: /core/api/authenticate/
Traceback (most recent call last):
  File "/Users/bedeabbe/Desktop/projects/python/venv/lib/python3.9/site-packages/django/core/handlers/exception.py", line 47, in inner
    response = get_response(request)
  File "/Users/bedeabbe/Desktop/projects/python/venv/lib/python3.9/site-packages/django/core/handlers/base.py", line 181, in _get_response
    response = wrapped_callback(request, *callback_args, **callback_kwargs)
  File "/Users/bedeabbe/Desktop/projects/python/venv/lib/python3.9/site-packages/django/views/decorators/csrf.py", line 54, in wrapped_view
    return view_func(*args, **kwargs)
  File "/Users/bedeabbe/Desktop/projects/python/venv/lib/python3.9/site-packages/rest_framework/viewsets.py", line 125, in view
    return self.dispatch(request, *args, **kwargs)
  File "/Users/bedeabbe/Desktop/projects/python/venv/lib/python3.9/site-packages/rest_framework/views.py", line 509, in dispatch
    response = self.handle_exception(exc)
  File "/Users/bedeabbe/Desktop/projects/python/venv/lib/python3.9/site-packages/rest_framework/views.py", line 469, in handle_exception
    self.raise_uncaught_exception(exc)
  File "/Users/bedeabbe/Desktop/projects/python/venv/lib/python3.9/site-packages/rest_framework/views.py", line 480, in raise_uncaught_exception
    raise exc
  File "/Users/bedeabbe/Desktop/projects/python/venv/lib/python3.9/site-packages/rest_framework/views.py", line 506, in dispatch
    response = handler(request, *args, **kwargs)
  File "/Users/bedeabbe/Desktop/projects/python/project_h_backend/project_h_core/auth_and_registration_views/authentication_view.py", line 49, in create
    return Response(authenticationResponseSerializer(resp).data,status.HTTP_202_ACCEPTED)
AttributeError: 'int' object has no attribute 'HTTP_202_ACCEPTED'
"POST /core/api/authenticate/ HTTP/1.1" 500 89778
/Users/bedeabbe/Desktop/projects/python/project_h_backend/project_h_core/auth_and_registration_views/authentication_view.py changed, reloading.
Watching for file changes with StatReloader
About to validate OTP
User details are 
jake.banky
Check password response is 
True
About to send response
"POST /core/api/authenticate/ HTTP/1.1" 202 48
/Users/bedeabbe/Desktop/projects/python/project_h_backend/project_h_core/auth_and_registration_views/authentication_view.py changed, reloading.
Watching for file changes with StatReloader
About to validate OTP
User details are 
jake.banky
Check password response is 
True
About to send response
"POST /core/api/authenticate/ HTTP/1.1" 202 48
/Users/bedeabbe/Desktop/projects/python/project_h_backend/project_h_core/auth_and_registration_views/authentication_view.py changed, reloading.
Watching for file changes with StatReloader
About to validate OTP
User details are 
jake.banky
Check password response is 
True
About to send response
"POST /core/api/authenticate/ HTTP/1.1" 202 48
About to validate OTP
User details are 
jake.banky
Check password response is 
False
About to send response
"POST /core/api/authenticate/ HTTP/1.1" 202 52
/Users/bedeabbe/Desktop/projects/python/project_h_backend/project_h_core/auth_and_registration_views/authentication_view.py changed, reloading.
Watching for file changes with StatReloader
Watching for file changes with StatReloader
Watching for file changes with StatReloader
Watching for file changes with StatReloader
/Users/bedeabbe/Desktop/projects/python/project_h_backend/project_h_core/auth_and_registration_views/authentication_view.py changed, reloading.
Watching for file changes with StatReloader
/Users/bedeabbe/Desktop/projects/python/project_h_backend/project_h_core/serializers.py changed, reloading.
Watching for file changes with StatReloader
/Users/bedeabbe/Desktop/projects/python/project_h_backend/project_h_core/auth_and_registration_views/authentication_view.py changed, reloading.
Watching for file changes with StatReloader
Bad Request: /core/api/authenticate/
"POST /core/api/authenticate/ HTTP/1.1" 400 36
/Users/bedeabbe/Desktop/projects/python/project_h_backend/project_h_core/serializers.py changed, reloading.
Watching for file changes with StatReloader
About to validate OTP
User details are 
jake.banky
Check password response is 
False
About to send response
"POST /core/api/authenticate/ HTTP/1.1" 202 985
About to validate OTP
User details are 
jake.banky
Check password response is 
False
About to send response
"POST /core/api/authenticate/ HTTP/1.1" 202 985
/Users/bedeabbe/Desktop/projects/python/project_h_backend/project_h_core/auth_and_registration_views/authentication_view.py changed, reloading.
Watching for file changes with StatReloader
About to validate OTP
User details are 
jake.banky
Check password response is 
False
About to send response
"POST /core/api/authenticate/ HTTP/1.1" 202 309
About to validate OTP
User details are 
jake.banky
Check password response is 
True
About to send response
"POST /core/api/authenticate/ HTTP/1.1" 202 981
About to save user 
{'mobile_number': '0269008514', 'first_name': 'Bede', 'last_name': 'Abbe', 'email': 'bede.abbe@gmail.com', 'gender': 'm', 'address': 'Fillin Street 229', 'password': 'terminal', 'dob': '1991-05-25'}
<built-in method today of type object at 0x10305dd38>
image is 
About to save customer details 
2024040620
Picture not there 
Customer saved 
"POST /core/api/register-customer/ HTTP/1.1" 202 925
About to save user 
{'mobile_number': '0269008514', 'first_name': 'Bede', 'last_name': 'Abbe', 'email': 'bede.abbe@gmail.com', 'gender': 'm', 'address': 'Fillin Street 229', 'password': 'terminal', 'dob': '1991-05-25'}
<built-in method today of type object at 0x10305dd38>
image is 
Internal Server Error: /core/api/register-customer/
Traceback (most recent call last):
  File "/Users/bedeabbe/Desktop/projects/python/venv/lib/python3.9/site-packages/django/db/backends/utils.py", line 84, in _execute
    return self.cursor.execute(sql, params)
  File "/Users/bedeabbe/Desktop/projects/python/venv/lib/python3.9/site-packages/django/db/backends/mysql/base.py", line 73, in execute
    return self.cursor.execute(query, args)
  File "/Users/bedeabbe/Desktop/projects/python/venv/lib/python3.9/site-packages/pymysql/cursors.py", line 148, in execute
    result = self._query(query)
  File "/Users/bedeabbe/Desktop/projects/python/venv/lib/python3.9/site-packages/pymysql/cursors.py", line 310, in _query
    conn.query(q)
  File "/Users/bedeabbe/Desktop/projects/python/venv/lib/python3.9/site-packages/pymysql/connections.py", line 548, in query
    self._affected_rows = self._read_query_result(unbuffered=unbuffered)
  File "/Users/bedeabbe/Desktop/projects/python/venv/lib/python3.9/site-packages/pymysql/connections.py", line 775, in _read_query_result
    result.read()
  File "/Users/bedeabbe/Desktop/projects/python/venv/lib/python3.9/site-packages/pymysql/connections.py", line 1156, in read
    first_packet = self.connection._read_packet()
  File "/Users/bedeabbe/Desktop/projects/python/venv/lib/python3.9/site-packages/pymysql/connections.py", line 725, in _read_packet
    packet.raise_for_error()
  File "/Users/bedeabbe/Desktop/projects/python/venv/lib/python3.9/site-packages/pymysql/protocol.py", line 221, in raise_for_error
    err.raise_mysql_exception(self._data)
  File "/Users/bedeabbe/Desktop/projects/python/venv/lib/python3.9/site-packages/pymysql/err.py", line 143, in raise_mysql_exception
    raise errorclass(errno, errval)
pymysql.err.IntegrityError: (1062, "Duplicate entry 'bede.abbe' for key 'auth_user.username'")

The above exception was the direct cause of the following exception:

Traceback (most recent call last):
  File "/Users/bedeabbe/Desktop/projects/python/venv/lib/python3.9/site-packages/django/core/handlers/exception.py", line 47, in inner
    response = get_response(request)
  File "/Users/bedeabbe/Desktop/projects/python/venv/lib/python3.9/site-packages/django/core/handlers/base.py", line 181, in _get_response
    response = wrapped_callback(request, *callback_args, **callback_kwargs)
  File "/Users/bedeabbe/Desktop/projects/python/venv/lib/python3.9/site-packages/django/views/decorators/csrf.py", line 54, in wrapped_view
    return view_func(*args, **kwargs)
  File "/Users/bedeabbe/Desktop/projects/python/venv/lib/python3.9/site-packages/rest_framework/viewsets.py", line 125, in view
    return self.dispatch(request, *args, **kwargs)
  File "/Users/bedeabbe/Desktop/projects/python/venv/lib/python3.9/site-packages/rest_framework/views.py", line 509, in dispatch
    response = self.handle_exception(exc)
  File "/Users/bedeabbe/Desktop/projects/python/venv/lib/python3.9/site-packages/rest_framework/views.py", line 469, in handle_exception
    self.raise_uncaught_exception(exc)
  File "/Users/bedeabbe/Desktop/projects/python/venv/lib/python3.9/site-packages/rest_framework/views.py", line 480, in raise_uncaught_exception
    raise exc
  File "/Users/bedeabbe/Desktop/projects/python/venv/lib/python3.9/site-packages/rest_framework/views.py", line 506, in dispatch
    response = handler(request, *args, **kwargs)
  File "/Users/bedeabbe/Desktop/projects/python/project_h_backend/project_h_core/auth_and_registration_views/register_views.py", line 52, in create
    save_user.save()
  File "/Users/bedeabbe/Desktop/projects/python/venv/lib/python3.9/site-packages/django/contrib/auth/base_user.py", line 67, in save
    super().save(*args, **kwargs)
  File "/Users/bedeabbe/Desktop/projects/python/venv/lib/python3.9/site-packages/django/db/models/base.py", line 753, in save
    self.save_base(using=using, force_insert=force_insert,
  File "/Users/bedeabbe/Desktop/projects/python/venv/lib/python3.9/site-packages/django/db/models/base.py", line 790, in save_base
    updated = self._save_table(
  File "/Users/bedeabbe/Desktop/projects/python/venv/lib/python3.9/site-packages/django/db/models/base.py", line 895, in _save_table
    results = self._do_insert(cls._base_manager, using, fields, returning_fields, raw)
  File "/Users/bedeabbe/Desktop/projects/python/venv/lib/python3.9/site-packages/django/db/models/base.py", line 933, in _do_insert
    return manager._insert(
  File "/Users/bedeabbe/Desktop/projects/python/venv/lib/python3.9/site-packages/django/db/models/manager.py", line 85, in manager_method
    return getattr(self.get_queryset(), name)(*args, **kwargs)
  File "/Users/bedeabbe/Desktop/projects/python/venv/lib/python3.9/site-packages/django/db/models/query.py", line 1254, in _insert
    return query.get_compiler(using=using).execute_sql(returning_fields)
  File "/Users/bedeabbe/Desktop/projects/python/venv/lib/python3.9/site-packages/django/db/models/sql/compiler.py", line 1397, in execute_sql
    cursor.execute(sql, params)
  File "/Users/bedeabbe/Desktop/projects/python/venv/lib/python3.9/site-packages/django/db/backends/utils.py", line 98, in execute
    return super().execute(sql, params)
  File "/Users/bedeabbe/Desktop/projects/python/venv/lib/python3.9/site-packages/django/db/backends/utils.py", line 66, in execute
    return self._execute_with_wrappers(sql, params, many=False, executor=self._execute)
  File "/Users/bedeabbe/Desktop/projects/python/venv/lib/python3.9/site-packages/django/db/backends/utils.py", line 75, in _execute_with_wrappers
    return executor(sql, params, many, context)
  File "/Users/bedeabbe/Desktop/projects/python/venv/lib/python3.9/site-packages/django/db/backends/utils.py", line 84, in _execute
    return self.cursor.execute(sql, params)
  File "/Users/bedeabbe/Desktop/projects/python/venv/lib/python3.9/site-packages/django/db/utils.py", line 90, in __exit__
    raise dj_exc_value.with_traceback(traceback) from exc_value
  File "/Users/bedeabbe/Desktop/projects/python/venv/lib/python3.9/site-packages/django/db/backends/utils.py", line 84, in _execute
    return self.cursor.execute(sql, params)
  File "/Users/bedeabbe/Desktop/projects/python/venv/lib/python3.9/site-packages/django/db/backends/mysql/base.py", line 73, in execute
    return self.cursor.execute(query, args)
  File "/Users/bedeabbe/Desktop/projects/python/venv/lib/python3.9/site-packages/pymysql/cursors.py", line 148, in execute
    result = self._query(query)
  File "/Users/bedeabbe/Desktop/projects/python/venv/lib/python3.9/site-packages/pymysql/cursors.py", line 310, in _query
    conn.query(q)
  File "/Users/bedeabbe/Desktop/projects/python/venv/lib/python3.9/site-packages/pymysql/connections.py", line 548, in query
    self._affected_rows = self._read_query_result(unbuffered=unbuffered)
  File "/Users/bedeabbe/Desktop/projects/python/venv/lib/python3.9/site-packages/pymysql/connections.py", line 775, in _read_query_result
    result.read()
  File "/Users/bedeabbe/Desktop/projects/python/venv/lib/python3.9/site-packages/pymysql/connections.py", line 1156, in read
    first_packet = self.connection._read_packet()
  File "/Users/bedeabbe/Desktop/projects/python/venv/lib/python3.9/site-packages/pymysql/connections.py", line 725, in _read_packet
    packet.raise_for_error()
  File "/Users/bedeabbe/Desktop/projects/python/venv/lib/python3.9/site-packages/pymysql/protocol.py", line 221, in raise_for_error
    err.raise_mysql_exception(self._data)
  File "/Users/bedeabbe/Desktop/projects/python/venv/lib/python3.9/site-packages/pymysql/err.py", line 143, in raise_mysql_exception
    raise errorclass(errno, errval)
django.db.utils.IntegrityError: (1062, "Duplicate entry 'bede.abbe' for key 'auth_user.username'")
"POST /core/api/register-customer/ HTTP/1.1" 500 243632
/Users/bedeabbe/Desktop/projects/python/project_h_backend/project_h_core/auth_and_registration_views/authentication_view.py changed, reloading.
Watching for file changes with StatReloader
/Users/bedeabbe/Desktop/projects/python/project_h_backend/project_h_core/auth_and_registration_views/authentication_view.py changed, reloading.
Watching for file changes with StatReloader
/Users/bedeabbe/Desktop/projects/python/project_h_backend/project_h/settings.py changed, reloading.
Watching for file changes with StatReloader
Watching for file changes with StatReloader
/Users/bedeabbe/Desktop/projects/python/project_h_backend/project_h/settings.py changed, reloading.
Watching for file changes with StatReloader
About to validate OTP
User details are 
bede.abbe
Check password response is 
True
About to send response
"POST /core/api/authenticate/ HTTP/1.1" 202 979
About to validate OTP
About to send response
"POST /core/api/authenticate/ HTTP/1.1" 202 64
About to validate OTP
About to send response
"POST /core/api/authenticate/ HTTP/1.1" 202 64
/Users/bedeabbe/Desktop/projects/python/project_h_backend/project_h_core/auth_and_registration_views/authentication_view.py changed, reloading.
Watching for file changes with StatReloader
About to validate OTP
About to send response
"POST /core/api/authenticate/ HTTP/1.1" 202 64
About to validate OTP
About to send response
"POST /core/api/authenticate/ HTTP/1.1" 202 64
/Users/bedeabbe/Desktop/projects/python/project_h_backend/project_h_core/auth_and_registration_views/authentication_view.py changed, reloading.
Watching for file changes with StatReloader
About to validate OTP
About to send response
"POST /core/api/authenticate/ HTTP/1.1" 202 64
/Users/bedeabbe/Desktop/projects/python/project_h_backend/project_h_core/auth_and_registration_views/authentication_view.py changed, reloading.
Watching for file changes with StatReloader
/Users/bedeabbe/Desktop/projects/python/project_h_backend/project_h_core/auth_and_registration_views/authentication_view.py changed, reloading.
Watching for file changes with StatReloader
About to validate user credentials
About to send response
"POST /core/api/authenticate/ HTTP/1.1" 202 64
/Users/bedeabbe/Desktop/projects/python/project_h_backend/project_h_core/auth_and_registration_views/authentication_view.py changed, reloading.
Watching for file changes with StatReloader
/Users/bedeabbe/Desktop/projects/python/project_h_backend/project_h_core/auth_and_registration_views/authentication_view.py changed, reloading.
Watching for file changes with StatReloader
About to validate user credentials
Getting user details
ERROR:::
User matching query does not exist.
About to send response
"POST /core/api/authenticate/ HTTP/1.1" 202 64
/Users/bedeabbe/Desktop/projects/python/project_h_backend/project_h_core/auth_and_registration_views/authentication_view.py changed, reloading.
Watching for file changes with StatReloader
About to validate user credentials
Getting user details
Internal Server Error: /core/api/authenticate/
Traceback (most recent call last):
  File "/Users/bedeabbe/Desktop/projects/python/venv/lib/python3.9/site-packages/django/core/handlers/exception.py", line 47, in inner
    response = get_response(request)
  File "/Users/bedeabbe/Desktop/projects/python/venv/lib/python3.9/site-packages/django/core/handlers/base.py", line 181, in _get_response
    response = wrapped_callback(request, *callback_args, **callback_kwargs)
  File "/Users/bedeabbe/Desktop/projects/python/venv/lib/python3.9/site-packages/django/views/decorators/csrf.py", line 54, in wrapped_view
    return view_func(*args, **kwargs)
  File "/Users/bedeabbe/Desktop/projects/python/venv/lib/python3.9/site-packages/rest_framework/viewsets.py", line 125, in view
    return self.dispatch(request, *args, **kwargs)
  File "/Users/bedeabbe/Desktop/projects/python/venv/lib/python3.9/site-packages/rest_framework/views.py", line 509, in dispatch
    response = self.handle_exception(exc)
  File "/Users/bedeabbe/Desktop/projects/python/venv/lib/python3.9/site-packages/rest_framework/views.py", line 469, in handle_exception
    self.raise_uncaught_exception(exc)
  File "/Users/bedeabbe/Desktop/projects/python/venv/lib/python3.9/site-packages/rest_framework/views.py", line 480, in raise_uncaught_exception
    raise exc
  File "/Users/bedeabbe/Desktop/projects/python/venv/lib/python3.9/site-packages/rest_framework/views.py", line 506, in dispatch
    response = handler(request, *args, **kwargs)
  File "/Users/bedeabbe/Desktop/projects/python/project_h_backend/project_h_core/auth_and_registration_views/authentication_view.py", line 36, in create
    user = User.objects.get(customers__mobile_number=serializer.data['username'])
  File "/Users/bedeabbe/Desktop/projects/python/venv/lib/python3.9/site-packages/django/db/models/manager.py", line 85, in manager_method
    return getattr(self.get_queryset(), name)(*args, **kwargs)
  File "/Users/bedeabbe/Desktop/projects/python/venv/lib/python3.9/site-packages/django/db/models/query.py", line 429, in get
    raise self.model.DoesNotExist(
django.contrib.auth.models.User.DoesNotExist: User matching query does not exist.
"POST /core/api/authenticate/ HTTP/1.1" 500 98444
/Users/bedeabbe/Desktop/projects/python/project_h_backend/project_h_core/auth_and_registration_views/authentication_view.py changed, reloading.
Watching for file changes with StatReloader
About to validate user credentials
Getting user details
ERROR...
User is 
bede.abbe
User details are 
bede.abbe
Check password response is 
True
About to send response
"POST /core/api/authenticate/ HTTP/1.1" 202 979
About to validate user credentials
Getting user details
ERROR...
ERROR.......
User is 

User details are 

Check password response is 
False
About to send response
"POST /core/api/authenticate/ HTTP/1.1" 202 309
About to validate user credentials
Getting user details
ERROR...
ERROR.......
User is 

User details are 

Check password response is 
False
About to send response
"POST /core/api/authenticate/ HTTP/1.1" 202 309
About to validate user credentials
Getting user details
User is 
bede.abbe
User details are 
bede.abbe
Check password response is 
True
About to send response
"POST /core/api/authenticate/ HTTP/1.1" 202 979
About to validate user credentials
Getting user details
ERROR...
ERROR.......
User is 

User details are 

Check password response is 
False
About to send response
"POST /core/api/authenticate/ HTTP/1.1" 202 309
About to validate user credentials
Getting user details
ERROR...
ERROR.......
User is 

User details are 

Check password response is 
False
About to send response
"POST /core/api/authenticate/ HTTP/1.1" 202 309
/Users/bedeabbe/Desktop/projects/python/project_h_backend/project_h_core/auth_and_registration_views/authentication_view.py changed, reloading.
Watching for file changes with StatReloader
About to validate user credentials
Getting user details
ERROR...
ERROR.......
User is 

User details are 

Check password response is 
False
About to send response
"POST /core/api/authenticate/ HTTP/1.1" 202 309
About to validate user credentials
Getting user details
ERROR...
ERROR.......
User is 

User details are 

Check password response is 
False
About to send response
"POST /core/api/authenticate/ HTTP/1.1" 202 309
/Users/bedeabbe/Desktop/projects/python/project_h_backend/project_h_core/auth_and_registration_views/authentication_view.py changed, reloading.
Watching for file changes with StatReloader
About to validate user credentials
Getting user details
ERROR...
Internal Server Error: /core/api/authenticate/
Traceback (most recent call last):
  File "/Users/bedeabbe/Desktop/projects/python/project_h_backend/project_h_core/auth_and_registration_views/authentication_view.py", line 38, in create
    user = User.objects.get(customers__mobile_number=serializer.data['username'])
  File "/Users/bedeabbe/Desktop/projects/python/venv/lib/python3.9/site-packages/django/db/models/manager.py", line 85, in manager_method
    return getattr(self.get_queryset(), name)(*args, **kwargs)
  File "/Users/bedeabbe/Desktop/projects/python/venv/lib/python3.9/site-packages/django/db/models/query.py", line 429, in get
    raise self.model.DoesNotExist(
django.contrib.auth.models.User.DoesNotExist: User matching query does not exist.

During handling of the above exception, another exception occurred:

Traceback (most recent call last):
  File "/Users/bedeabbe/Desktop/projects/python/project_h_backend/project_h_core/auth_and_registration_views/authentication_view.py", line 42, in create
    logger.info("About to check in users table with email ".serializer.data['username'])
AttributeError: 'str' object has no attribute 'serializer'

During handling of the above exception, another exception occurred:

Traceback (most recent call last):
  File "/Users/bedeabbe/Desktop/projects/python/venv/lib/python3.9/site-packages/django/core/handlers/exception.py", line 47, in inner
    response = get_response(request)
  File "/Users/bedeabbe/Desktop/projects/python/venv/lib/python3.9/site-packages/django/core/handlers/base.py", line 181, in _get_response
    response = wrapped_callback(request, *callback_args, **callback_kwargs)
  File "/Users/bedeabbe/Desktop/projects/python/venv/lib/python3.9/site-packages/django/views/decorators/csrf.py", line 54, in wrapped_view
    return view_func(*args, **kwargs)
  File "/Users/bedeabbe/Desktop/projects/python/venv/lib/python3.9/site-packages/rest_framework/viewsets.py", line 125, in view
    return self.dispatch(request, *args, **kwargs)
  File "/Users/bedeabbe/Desktop/projects/python/venv/lib/python3.9/site-packages/rest_framework/views.py", line 509, in dispatch
    response = self.handle_exception(exc)
  File "/Users/bedeabbe/Desktop/projects/python/venv/lib/python3.9/site-packages/rest_framework/views.py", line 469, in handle_exception
    self.raise_uncaught_exception(exc)
  File "/Users/bedeabbe/Desktop/projects/python/venv/lib/python3.9/site-packages/rest_framework/views.py", line 480, in raise_uncaught_exception
    raise exc
  File "/Users/bedeabbe/Desktop/projects/python/venv/lib/python3.9/site-packages/rest_framework/views.py", line 506, in dispatch
    response = handler(request, *args, **kwargs)
  File "/Users/bedeabbe/Desktop/projects/python/project_h_backend/project_h_core/auth_and_registration_views/authentication_view.py", line 45, in create
    logger.error("Error.....".e)
AttributeError: 'str' object has no attribute 'e'
"POST /core/api/authenticate/ HTTP/1.1" 500 109306
/Users/bedeabbe/Desktop/projects/python/project_h_backend/project_h_core/auth_and_registration_views/authentication_view.py changed, reloading.
Watching for file changes with StatReloader
About to validate user credentials
Getting user details
ERROR...
About to check in users table with email bede.abbe@gmail.com
Internal Server Error: /core/api/authenticate/
Traceback (most recent call last):
  File "/Users/bedeabbe/Desktop/projects/python/project_h_backend/project_h_core/auth_and_registration_views/authentication_view.py", line 38, in create
    user = User.objects.get(customers__mobile_number=serializer.data['username'])
  File "/Users/bedeabbe/Desktop/projects/python/venv/lib/python3.9/site-packages/django/db/models/manager.py", line 85, in manager_method
    return getattr(self.get_queryset(), name)(*args, **kwargs)
  File "/Users/bedeabbe/Desktop/projects/python/venv/lib/python3.9/site-packages/django/db/models/query.py", line 429, in get
    raise self.model.DoesNotExist(
django.contrib.auth.models.User.DoesNotExist: User matching query does not exist.

During handling of the above exception, another exception occurred:

Traceback (most recent call last):
  File "/Users/bedeabbe/Desktop/projects/python/project_h_backend/project_h_core/auth_and_registration_views/authentication_view.py", line 43, in create
    user = User.objects.get(email=serializer.data['username'])
  File "/Users/bedeabbe/Desktop/projects/python/venv/lib/python3.9/site-packages/django/db/models/manager.py", line 85, in manager_method
    return getattr(self.get_queryset(), name)(*args, **kwargs)
  File "/Users/bedeabbe/Desktop/projects/python/venv/lib/python3.9/site-packages/django/db/models/query.py", line 433, in get
    raise self.model.MultipleObjectsReturned(
django.contrib.auth.models.User.MultipleObjectsReturned: get() returned more than one User -- it returned 2!

During handling of the above exception, another exception occurred:

Traceback (most recent call last):
  File "/Users/bedeabbe/Desktop/projects/python/venv/lib/python3.9/site-packages/django/core/handlers/exception.py", line 47, in inner
    response = get_response(request)
  File "/Users/bedeabbe/Desktop/projects/python/venv/lib/python3.9/site-packages/django/core/handlers/base.py", line 181, in _get_response
    response = wrapped_callback(request, *callback_args, **callback_kwargs)
  File "/Users/bedeabbe/Desktop/projects/python/venv/lib/python3.9/site-packages/django/views/decorators/csrf.py", line 54, in wrapped_view
    return view_func(*args, **kwargs)
  File "/Users/bedeabbe/Desktop/projects/python/venv/lib/python3.9/site-packages/rest_framework/viewsets.py", line 125, in view
    return self.dispatch(request, *args, **kwargs)
  File "/Users/bedeabbe/Desktop/projects/python/venv/lib/python3.9/site-packages/rest_framework/views.py", line 509, in dispatch
    response = self.handle_exception(exc)
  File "/Users/bedeabbe/Desktop/projects/python/venv/lib/python3.9/site-packages/rest_framework/views.py", line 469, in handle_exception
    self.raise_uncaught_exception(exc)
  File "/Users/bedeabbe/Desktop/projects/python/venv/lib/python3.9/site-packages/rest_framework/views.py", line 480, in raise_uncaught_exception
    raise exc
  File "/Users/bedeabbe/Desktop/projects/python/venv/lib/python3.9/site-packages/rest_framework/views.py", line 506, in dispatch
    response = handler(request, *args, **kwargs)
  File "/Users/bedeabbe/Desktop/projects/python/project_h_backend/project_h_core/auth_and_registration_views/authentication_view.py", line 45, in create
    logger.error("Error....."+e)
TypeError: can only concatenate str (not "MultipleObjectsReturned") to str
"POST /core/api/authenticate/ HTTP/1.1" 500 118172
About to validate user credentials
Getting user details
ERROR...
About to check in users table with email bede.abbe@gmail.com
Internal Server Error: /core/api/authenticate/
Traceback (most recent call last):
  File "/Users/bedeabbe/Desktop/projects/python/project_h_backend/project_h_core/auth_and_registration_views/authentication_view.py", line 38, in create
    user = User.objects.get(customers__mobile_number=serializer.data['username'])
  File "/Users/bedeabbe/Desktop/projects/python/venv/lib/python3.9/site-packages/django/db/models/manager.py", line 85, in manager_method
    return getattr(self.get_queryset(), name)(*args, **kwargs)
  File "/Users/bedeabbe/Desktop/projects/python/venv/lib/python3.9/site-packages/django/db/models/query.py", line 429, in get
    raise self.model.DoesNotExist(
django.contrib.auth.models.User.DoesNotExist: User matching query does not exist.

During handling of the above exception, another exception occurred:

Traceback (most recent call last):
  File "/Users/bedeabbe/Desktop/projects/python/project_h_backend/project_h_core/auth_and_registration_views/authentication_view.py", line 43, in create
    user = User.objects.get(email=serializer.data['username'])
  File "/Users/bedeabbe/Desktop/projects/python/venv/lib/python3.9/site-packages/django/db/models/manager.py", line 85, in manager_method
    return getattr(self.get_queryset(), name)(*args, **kwargs)
  File "/Users/bedeabbe/Desktop/projects/python/venv/lib/python3.9/site-packages/django/db/models/query.py", line 433, in get
    raise self.model.MultipleObjectsReturned(
django.contrib.auth.models.User.MultipleObjectsReturned: get() returned more than one User -- it returned 2!

During handling of the above exception, another exception occurred:

Traceback (most recent call last):
  File "/Users/bedeabbe/Desktop/projects/python/venv/lib/python3.9/site-packages/django/core/handlers/exception.py", line 47, in inner
    response = get_response(request)
  File "/Users/bedeabbe/Desktop/projects/python/venv/lib/python3.9/site-packages/django/core/handlers/base.py", line 181, in _get_response
    response = wrapped_callback(request, *callback_args, **callback_kwargs)
  File "/Users/bedeabbe/Desktop/projects/python/venv/lib/python3.9/site-packages/django/views/decorators/csrf.py", line 54, in wrapped_view
    return view_func(*args, **kwargs)
  File "/Users/bedeabbe/Desktop/projects/python/venv/lib/python3.9/site-packages/rest_framework/viewsets.py", line 125, in view
    return self.dispatch(request, *args, **kwargs)
  File "/Users/bedeabbe/Desktop/projects/python/venv/lib/python3.9/site-packages/rest_framework/views.py", line 509, in dispatch
    response = self.handle_exception(exc)
  File "/Users/bedeabbe/Desktop/projects/python/venv/lib/python3.9/site-packages/rest_framework/views.py", line 469, in handle_exception
    self.raise_uncaught_exception(exc)
  File "/Users/bedeabbe/Desktop/projects/python/venv/lib/python3.9/site-packages/rest_framework/views.py", line 480, in raise_uncaught_exception
    raise exc
  File "/Users/bedeabbe/Desktop/projects/python/venv/lib/python3.9/site-packages/rest_framework/views.py", line 506, in dispatch
    response = handler(request, *args, **kwargs)
  File "/Users/bedeabbe/Desktop/projects/python/project_h_backend/project_h_core/auth_and_registration_views/authentication_view.py", line 45, in create
    logger.error("Error....."+e)
TypeError: can only concatenate str (not "MultipleObjectsReturned") to str
"POST /core/api/authenticate/ HTTP/1.1" 500 118172
About to validate user credentials
Getting user details
ERROR...
About to check in users table with email bede.abbe@gmail.com
User is 
bede.abbe
User details are 
bede.abbe
Check password response is 
True
About to send response
"POST /core/api/authenticate/ HTTP/1.1" 202 979
/Users/bedeabbe/Desktop/projects/python/project_h_backend/project_h_core/auth_and_registration_views/register_views.py changed, reloading.
Watching for file changes with StatReloader
/Users/bedeabbe/Desktop/projects/python/project_h_backend/project_h_core/urls.py changed, reloading.
Watching for file changes with StatReloader
About to save user 
{'username': 'bede.abbe@gmail.com', 'password': 'terminal2'}
<built-in method today of type object at 0x1027b5d38>
ERROR...
About to check in users table with email bede.abbe@gmail.com
"POST /core/api/update-customer-password/ HTTP/1.1" 202 854
/Users/bedeabbe/Desktop/projects/python/project_h_backend/project_h_core/auth_and_registration_views/register_views.py changed, reloading.
Watching for file changes with StatReloader
About to save user 
{'username': 'bede.abbe@gmail.com', 'password': 'terminal2'}
<built-in method today of type object at 0x104fb9d38>
ERROR...
About to check in users table with email bede.abbe@gmail.com
"POST /core/api/update-customer-password/ HTTP/1.1" 202 923
About to validate user credentials
Getting user details
ERROR...
About to check in users table with email bede.abbe@gmail.com
User is 
bede.abbe
User details are 
bede.abbe
Check password response is 
False
About to send response
"POST /core/api/authenticate/ HTTP/1.1" 202 309
About to validate user credentials
Getting user details
ERROR...
About to check in users table with email bede.abbe@gmail.com
User is 
bede.abbe
User details are 
bede.abbe
Check password response is 
True
About to send response
"POST /core/api/authenticate/ HTTP/1.1" 202 979
/Users/bedeabbe/Desktop/projects/python/project_h_backend/project_h/settings.py changed, reloading.
Watching for file changes with StatReloader
Watching for file changes with StatReloader
/Users/bedeabbe/Desktop/projects/python/project_h_backend/project_h_core/auth_and_registration_views/authentication_view.py changed, reloading.
Watching for file changes with StatReloader
/Users/bedeabbe/Desktop/projects/python/project_h_backend/project_h/settings.py changed, reloading.
Watching for file changes with StatReloader
